Workbook
Name Lista_coccion: [3]Hoja2!$F$6:$F$17

Sheet General
A2: 2.1. | B2: Medida de Cocción limpia (ámbito rural)
B4: Implementación y sostenibilidad de tecnologías de cocción limpia (cocinas mejoradas y cocinas a gas licuado de petróleos) en zonas rurales, reemplazando aquellas cocinas o tecnologías convencionales (fogón abierto) poco eficientes en el ámbito rural, con lo cual se reducirá los consumos de combustibles empleados en cocinas tradicionales, tales como leña y carbón vegetal, reduciendo así emisiones de gases de efecto invernadero (GEI) y los efectos nocivos a la salud asociados a las emisiones gaseosas y del material particulado restante de la combustión.
B8: Medida | C8: Finalidad | D8: Indicadores | E8: Fuente (s)
B9: Cocción limpia | C9: Se enfoca en la reducción de las emisiones de gases de efecto invernadero (GEI) generadas por la cocción y calentamiento de alimentos a través del uso de cocinas o tecnologías convencionales (fogón abierto) poco eficientes en el ámbito rural. Incluye: cocinas mejoradas y a gas licuado de petróleo (GLP). | D9: Número de cocinas, combustible por cocina, vales GLP, biomasa no renovable | E9: FONCODES, FISE
B11: Metodología (Fogon-Mejorada)
B13: Ecuación 1
B14: ER = {(BCb,y - PCp,y) ∙ [(fNRB,y ∙ EFb,leña,CO2) + EFb,leña,CH4 ∙ PCGCH4 + EFb,leña,N2O ∙ PCGN2O] ∙ NCVb,leña} ∙ CI
B16: Donde:
B17: ER | C17: Emisiones reducidas durante el año "y" en tCO2e
B18: BCb,y | C18: Cantidad de combustible consumido en la Línea de Base b durante un año "y" (t)
B19: PCp,y | C19: Cantidad de combustible consumido en Proyecto p durante un año "y"
B20: fNRB,y | C20: Fracción de biomasa no renovable usada durante un año "y"
B21: EFb,leña,CO2 | C21: Factor de emisión de CO2 de la leña.
B22: EFb,leña,CH4 | C22: Factor de emisión de metano (CH4) de la leña.
B23: PCGCH4 | C23: Potencial de Calentamiento Global del Metano
B24: EFb,fuel,N2O | C24: Factor de emisión de óxido nitroso (N2O) de la leña.
B25: PCGN2O | C25: Potencial de Calentamiento Global del Óxido Nitroso
B26: NCVb,fuel | C26: Valor Calorífico Neto del combustible (valor predeterminado del IPCC para madera: 0.015TJ/t
B27: CI | C27: Cocinas instaladas
B29: Metodología (Fogon-GLP)
B31: Ecuación 2
B32: ER = {BCb,y ∙ [(fNRB,y ∙ EFb,leña,CO2) + EFb,leña,CH4 ∙ PCGCH4 + EFb,leña,N2O ∙ PCGN2O] ∙ NCVb,leña} - {[PCp,y ∙ (EFb,GLP,CO2 + EFb,GLP,CH4 ∙ PCGCH4 + EFb,GLP,N2O ∙ PCGN2O)]∙ NCVb,GLP} ∙ CI
B34: Donde:
B35: ER | C35: Emisiones para la Línea de Base b durante el año "y" en tCO2e
B36: BCb,y | C36: Cantidad de combustible consumido en la Línea de Base b durante un año "y" (t)
B37: fNRB,y | C37: Fracción de biomasa no renovable usada durante un año "y"
B38: EFb,leña,CO2 | C38: Factor de emisión de CO2 de la leña.
B39: EFb,leña,CH4 | C39: Factor de emisión de metano (CH4) de la leña.
B40: PCGCH4 | C40: Potencial de Calentamiento Global del Metano
B41: EFb,leña,N2O | C41: Factor de emisión de óxido nitroso (N2O) de la leña.
B42: PCGN2O | C42: Potencial de Calentamiento Global del Óxido Nitroso
B43: NCVb,leña | C43: Valor Calorífico Neto de la leña
B44: PCp,y | C44: Cantidad de combustible consumido en Proyecto p durante un año "y"
B45: EFb,GLP,CO2 | C45: Factor de emisión de CO2 de GLP.
B46: EFb,GLP,CH4 | C46: Factor de emisión de metano (CH4) de GLP.
... B51: CI | C51: Cocinas instaladas

Sheet Proveedores
A2: 2.1. | B2: Medida de Cocción limpia (ámbito rural)
B4: PROVEEDORES
B5: Diseño detallado | D5: Programación Tentativa Sectorial
B6: 1. MIDIS-FONCODES 2. OSINERGMIN-FISE | D6: 1. MIDIS-FONCODES 2. OSINERGMIN-FISE
B7: 3. Consultoría/MICROSOL (NRBf) | D7: 3. Consultoría
B9: Etapa | C9: Información | D9: Fuente | E9: Responsable | F9: Frecuencia | G9: ¿Requiere acuerdo?
B10: Cocción limpia
B11: M | C11: Tecnologías de cocción limpia. Instaladas en programas financiados por el estado | D11: FONCODES Y OSINERGMIN | E11: DGEE | F11: Anual | G11: Si
C12: Vales de GLP canjeados por el financiamiento del programa FISE. | D12: OSINERGMIN | E12: DGEE | F12: Anual | G12: Si
C13: Fracción de Biomasa No Renovable | D13: Consultoría | E13: DGEE | F13: 06 años | G13: No
B14: R | C14: Efecto del reemplazo de cocinas tradicionales (fogon) por otras mejoradas | D14: DGEE en base a información de FONCODES y OSINERGMIN | E14: DGEE | F14: Bienal | G14: No
B15: V | C15: Reportes generados por DGEE, procedimientos de medición, otra información de soporte | D15: DGEE | E15: Auditor externo | F15: Cada 2 años o según lo demanden algunas autoridades o donantes | G15: No

Sheet Formato
B2: BaU | D2: Mitigación
B3: Tipo | C3: Consumo (t leña/SA.año) | D3: Tipo | E3: Consumo (t leña/SA.año) | F3: Cantidad | G3: Región | H3: Año | I3: Emisiones de GEI reducidas (tCO2e)
B4: Especificación de la fuente de cocción | C4: Variable propia de cada tipo de cocina | D4: Nombre de la tecnología de cocción | E4: Variable propia de cada tipo de cocina | F4: Número de unidades de este tipo, clase y descripción. | G4: Región donde fueron instaladas, según departamentos, las cocinas | H4: Año al que corresponde el registro. | I4: Emisiones de GEI que fueron reducidas | K4: Línea base | L4: Proyecto | M4: GEI reducido | N4: QC
B5: Tres piedras | C5: 2.8233333 | D5: Inkawasi 3 Hornillas | E5: =SUMIF(Variables!$B$4:$B$15,Formato!D5,Variables!$C$4:$C$15) -> 1.42 | F5: 12617 | G5: Sierra | H5: 2010 | I5: =(C5-E5)*((Factores!$E$4*Factores!$L$4)+Factores!$N$4*Factores!$L$20+Factores!$P$4*Factores!$L$21)*Factores!$J$4*F5*Variables!$C$18 -> 47547.024 | K5: =Factores!$J$4*C5*F5*(Factores!$E$4*Factores!$L$4+Factores!$N$4*Factores!$L$20+Factores!$P$4*Factores!$L$21)*Variables!$C$18 -> 95658.74 | L5: =Factores!$J$4*E5*F5*(Factores!$E$4*Factores!$L$4+Factores!$N$4*Factores!$L$20+Factores!$P$4*Factores!$L$21)*Variables!$C$18 -> 48111.716 | M5: =K5-L5 -> 47547.024 | N5: =I5-M5 -> 0
B6: Tres piedras | C6: 2.8233333 | D6: Inkawasi Pichqa | E6: =SUMIF(Variables!$B$4:$B$15,Formato!D6,Variables!$C$4:$C$15) -> 0.84 | F6: 719 | G6: Costa | H6: 2010 | I6: =(C6-E6)*((Factores!$D$4*Factores!$L$4)+Factores!$N$4*Factores!$L$20+Factores!$P$4*Factores!$L$21)*Factores!$J$4*F6*Variables!$C$18 -> 4586.8294 | K6: =Factores!$J$4*C6*F6*(Factores!$D$4*Factores!$L$4+Factores!$N$4*Factores!$L$20+Factores!$P$4*Factores!$L$21)*Variables!$C$18 -> 6529.4865 | L6: =Factores!$J$4*E6*F6*(Factores!$D$4*Factores!$L$4+Factores!$N$4*Factores!$L$20+Factores!$P$4*Factores!$L$21)*Variables!$C$18 -> 1942.6571 | M6: =K6-L6 -> 4586.8294 | N6: =I6-M6 -> 0
B7: Tres piedras | C7: 2.8233333 | D7: Inkawasi Pichqa | E7: =SUMIF(Variables!$B$4:$B$15,Formato!D7,Variables!$C$4:$C$15) -> 0.84 | F7: 4702 | G7: Sierra | H7: 2010 | I7: =(C7-E7)*((Factores!$E$4*Factores!$L$4)+Factores!$N$4*Factores!$L$20+Factores!$P$4*Factores!$L$21)*Factores!$J$4*F7*Variables!$C$18 -> 25042.907 | K7: =Factores!$J$4*C7*F7*(Factores!$E$4*Factores!$L$4+Factores!$N$4*Factores!$L$20+Factores!$P$4*Factores!$L$21)*Variables!$C$18 -> 35649.314 | L7: =Factores!$J$4*E7*F7*(Factores!$E$4*Factores!$L$4+Factores!$N$4*Factores!$L$20+Factores!$P$4*Factores!$L$21)*Variables!$C$18 -> 10606.407 | M7: =K7-L7 -> 25042.907 | N7: =I7-M7 -> 0
B8: Tres piedras | C8: 2.8233333 | D8: Inkawasi Pichqa | E8: =SUMIF(Variables!$B$4:$B$15,Formato!D8,Variables!$C$4:$C$15) -> 0.84 | F8: 1094 | G8: Selva | H8: 2010 | I8: =(C8-E8)*((Factores!$F$4*Factores!$L$4)+Factores!$N$4*Factores!$L$20+Factores!$P$4*Factores!$L$21)*Factores!$J$4*F8*Variables!$C$18 -> 5250.4222 | K8: =Factores!$J$4*C8*F8*(Factores!$F$4*Factores!$L$4+Factores!$N$4*Factores!$L$20+Factores!$P$4*Factores!$L$21)*Variables!$C$18 -> 7474.1304 | L8: =Factores!$J$4*E8*F8*(Factores!$F$4*Factores!$L$4+Factores!$N$4*Factores!$L$20+Factores!$P$4*Factores!$L$21)*Variables!$C$18 -> 2223.7082 | M8: =K8-L8 -> 5250.4222 | N8: =I8-M8 -> 0
B9: Tres piedras | C9: 2.8233333 | D9: Inkawasi Sojta | E9: =SUMIF(Variables!$B$4:$B$15,Formato!D9,Variables!$C$4:$C$15) -> 1.8 | F9: 1060 | G9: Costa | H9: 2010 | I9: =(C9-E9)*((Factores!$D$4*Factores!$L$4)+Factores!$N$4*Factores!$L$20+Factores!$P$4*Factores!$L$21)*Factores!$J$4*F9*Variables!$C$18 -> 3489.0803 | K9: =Factores!$J$4*C9*F9*(Factores!$D$4*Factores!$L$4+Factores!$N$4*Factores!$L$20+Factores!$P$4*Factores!$L$21)*Variables!$C$18 -> 9626.2249 | L9: =Factores!$J$4*E9*F9*(Factores!$D$4*Factores!$L$4+Factores!$N$4*Factores!$L$20+Factores!$P$4*Factores!$L$21)*Variables!$C$18 -> 6137.1446 | M9: =K9-L9 -> 3489.0803 | N9: =I9-M9 -> 0
B10: Tres piedras | C10: 2.8233333 | D10: Inkawasi Tawa | E10: =SUMIF(Variables!$B$4:$B$15,Formato!D10,Variables!$C$4:$C$15) -> 1.53 | F10: 703 | G10: Costa | H10: 2010 | I10: =(C10-E10)*((Factores!$D$4*Factores!$L$4)+Factores!$N$4*Factores!$L$20+Factores!$P$4*Factores!$L$21)*Factores!$J$4*F10*Variables!$C$18 -> 2924.5145 | K10: =Factores!$J$4*C10*F10*(Factores!$D$4*Factores!$L$4+Factores!$N$4*Factores!$L$20+Factores!$P$4*Factores!$L$21)*Variables!$C$18 -> 6384.185 | L10: =Factores!$J$4*E10*F10*(Factores!$D$4*Factores!$L$4+Factores!$N$4*Factores!$L$20+Factores!$P$4*Factores!$L$21)*Variables!$C$18 -> 3459.6705 | M10: =K10-L10 -> 2924.5145 | N10: =I10-M10 -> 0
B11: Tres piedras | C11: 2.8233333 | D11: Inkawasi Tawa | E11: =SUMIF(Variables!$B$4:$B$15,Formato!D11,Variables!$C$4:$C$15) -> 1.53 | F11: 19526 | G11: Sierra | H11: 2010 | I11: =(C11-E11)*((Factores!$E$4*Factores!$L$4)+Factores!$N$4*Factores!$L$20+Factores!$P$4*Factores!$L$21)*Factores!$J$4*F11*Variables!$C$18 -> 67815.685 | K11: =Factores!$J$4*C11*F11*(Factores!$E$4*Factores!$L$4+Factores!$N$4*Factores!$L$20+Factores!$P$4*Factores!$L$21)*Variables!$C$18 -> 148040.94 | L11: =Factores!$J$4*E11*F11*(Factores!$E$4*Factores!$L$4+Factores!$N$4*Factores!$L$20+Factores!$P$4*Factores!$L$21)*Variables!$C$18 -> 80225.256 | M11: =K11-L11 -> 67815.685 | N11: =I11-M11 -> 0
B12: Tres piedras | C12: 2.8233333 | D12: Inkawasi Plancha | E12: =SUMIF(Variables!$B$4:$B$15,Formato!D12,Variables!$C$4:$C$15) -> 1.9 | F12: 2551 | G12: Costa | H12: 2010 | I12: =(C12-E12)*((Factores!$D$4*Factores!$L$4)+Factores!$N$4*Factores!$L$20+Factores!$P$4*Factores!$L$21)*Factores!$J$4*F12*Variables!$C$18 -> 7576.2964 | K12: =Factores!$J$4*C12*F12*(Factores!$D$4*Factores!$L$4+Factores!$N$4*Factores!$L$20+Factores!$P$4*Factores!$L$21)*Variables!$C$18 -> 23166.509 | L12: =Factores!$J$4*E12*F12*(Factores!$D$4*Factores!$L$4+Factores!$N$4*Factores!$L$20+Factores!$P$4*Factores!$L$21)*Variables!$C$18 -> 15590.213 | M12: =K12-L12 -> 7576.2964
B13: Tres piedras | C13: 2.8233333 | D13: Inkawasi UK | E13: =SUMIF(Variables!$B$4:$B$15,Formato!D13,Variables!$C$4:$C$15) -> 2 | F13: 1446 | G13: Costa | H13: 2010 | I13: =(C13-E13)*((Factores!$D$4*Factores!$L$4)+Factores!$N$4*Factores!$L$20+Factores!$P$4*Factores!$L$21)*Factores!$J$4*F13*Variables!$C$18 -> 3829.411 | K13: =Factores!$J$4*C13*F13*(Factores!$D$4*Factores!$L$4+Factores!$N$4*Factores!$L$20+Factores!$P$4*Factores!$L$21)*Variables!$C$18 -> 13131.624 | L13: =Factores!$J$4*E13*F13*(Factores!$D$4*Factores!$L$4+Factores!$N$4*Factores!$L$20+Factores!$P$4*Factores!$L$21)*Variables!$C$18 -> 9302.2129 | M13: =K13-L13 -> 3829.411
B14: Tres piedras | C14: 2.8233333 | D14: Inkawasi UK | E14: =SUMIF(Variables!$B$4:$B$15,Formato!D14,Variables!$C$4:$C$15) -> 2 | F14: 449 | G14: Sierra | H14: 2010 | I14: =(C14-E14)*((Factores!$E$4*Factores!$L$4)+Factores!$N$4*Factores!$L$20+Factores!$P$4*Factores!$L$21)*Factores!$J$4*F14*Variables!$C$18 -> 992.72381 | K14: =Factores!$J$4*C14*F14*(Factores!$E$4*Factores!$L$4+Factores!$N$4*Factores!$L$20+Factores!$P$4*Factores!$L$21)*Variables!$C$18 -> 3404.1986 | L14: =Factores!$J$4*E14*F14*(Factores!$E$4*Factores!$L$4+Factores!$N$4*Factores!$L$20+Factores!$P$4*Factores!$L$21)*Variables!$C$18 -> 2411.4748 | M14: =K14-L14 -> 992.72381 | N14: =I14-M14 -> 0
B15: Total | I15: =SUM(I5:I14) -> 169054.89
B16: Tres piedras | C16: 2.8233333 | D16: Inkawasi 3 Hornillas | E16: =SUMIF(Variables!$B$4:$B$15,Formato!D16,Variables!$C$4:$C$15) -> 1.42 | F16: 41203 | G16: Sierra | H16: 2011 | I16: =(C16-E16)*((Factores!$E$5*Factores!$L$4)+Factores!$N$4*Factores!$L$20+Factores!$P$4*Factores!$L$21)*Factores!$J$4*F16*Variables!$C$18 -> 147595.09 | K16: =Factores!$J$4*C16*F16*(Factores!$E$5*Factores!$L$4+Factores!$N$4*Factores!$L$20+Factores!$P$4*Factores!$L$21)*Variables!$C$18 -> 296943.08 | L16: =Factores!$J$4*E16*F16*(Factores!$E$5*Factores!$L$4+Factores!$N$4*Factores!$L$20+Factores!$P$4*Factores!$L$21)*Variables!$C$18 -> 149348 | M16: =K16-L16 -> 147595.09 | N16: =I16-M16 -> 0
B17: Tres piedras | C17: 2.8233333 | D17: Inkawasi Pichqa | E17: =SUMIF(Variables!$B$4:$B$15,Formato!D17,Variables!$C$4:$C$15) -> 0.84 | F17: 719 | G17: Costa | H17: 2011 | I17: =(C17-E17)*((Factores!$D$5*Factores!$L$4)+Factores!$N$4*Factores!$L$20+Factores!$P$4*Factores!$L$21)*Factores!$J$4*F17*Variables!$C$18 -> 4681.5078 | K17: =Factores!$J$4*C17*F17*(Factores!$D$5*Factores!$L$4+Factores!$N$4*Factores!$L$20+Factores!$P$4*Factores!$L$21)*Variables!$C$18 -> 6664.264 | L17: =Factores!$J$4*E17*F17*(Factores!$D$5*Factores!$L$4+Factores!$N$4*Factores!$L$20+Factores!$P$4*Factores!$L$21)*Variables!$C$18 -> 1982.7562 | M17: =K17-L17 -> 4681.5078 | N17: =I17-M17 -> 0
B18: Tres piedras | C18: 2.8233333 | D18: Inkawasi Pichqa | E18: =SUMIF(Variables!$B$4:$B$15,Formato!D18,Variables!$C$4:$C$15) -> 0.84 | F18: 4702 | G18: Sierra | H18: 2011 | I18: =(C18-E18)*((Factores!$E$5*Factores!$L$4)+Factores!$N$4*Factores!$L$20+Factores!$P$4*Factores!$L$21)*Factores!$J$4*F18*Variables!$C$18 -> 23804.582 | K18: =Factores!$J$4*C18*F18*(Factores!$E$5*Factores!$L$4+Factores!$N$4*Factores!$L$20+Factores!$P$4*Factores!$L$21)*Variables!$C$18 -> 33886.522 | L18: =Factores!$J$4*E18*F18*(Factores!$E$5*Factores!$L$4+Factores!$N$4*Factores!$L$20+Factores!$P$4*Factores!$L$21)*Variables!$C$18 -> 10081.941 | M18: =K18-L18 -> 23804.582 | N18: =I18-M18 -> 0
B19: Tres piedras | C19: 2.8233333 | D19: Inkawasi Pichqa | E19: =SUMIF(Variables!$B$4:$B$15,Formato!D19,Variables!$C$4:$C$15) -> 0.84 | F19: 8030 | G19: Selva | H19: 2011 | I19: =(C19-E19)*((Factores!$F$5*Factores!$L$4)+Factores!$N$4*Factores!$L$20+Factores!$P$4*Factores!$L$21)*Factores!$J$4*F19*Variables!$C$18 -> 29021.731 | K19: =Factores!$J$4*C19*F19*(Factores!$F$5*Factores!$L$4+Factores!$N$4*Factores!$L$20+Factores!$P$4*Factores!$L$21)*Variables!$C$18 -> 41313.288 | L19: =Factores!$J$4*E19*F19*(Factores!$F$5*Factores!$L$4+Factores!$N$4*Factores!$L$20+Factores!$P$4*Factores!$L$21)*Variables!$C$18 -> 12291.557 | M19: =K19-L19 -> 29021.731 | N19: =I19-M19 -> 0
B20: Tres piedras | C20: 2.8233333 | D20: Inkawasi Sojta | E20: =SUMIF(Variables!$B$4:$B$15,Formato!D20,Variables!$C$4:$C$15) -> 1.8 | F20: 7355 | G20: Costa | H20: 2011 | I20: =(C20-E20)*((Factores!$D$5*Factores!$L$4)+Factores!$N$4*Factores!$L$20+Factores!$P$4*Factores!$L$21)*Factores!$J$4*F20*Variables!$C$18 -> 24709.329 | K20: =Factores!$J$4*C20*F20*(Factores!$D$5*Factores!$L$4+Factores!$N$4*Factores!$L$20+Factores!$P$4*Factores!$L$21)*Variables!$C$18 -> 68171.991 | L20: =Factores!$J$4*E20*F20*(Factores!$D$5*Factores!$L$4+Factores!$N$4*Factores!$L$20+Factores!$P$4*Factores!$L$21)*Variables!$C$18 -> 43462.663 | M20: =K20-L20 -> 24709.329 | N20: =I20-M20 -> 0
B21: Tres piedras | C21: 2.8233333 | D21: Inkawasi Tawa | E21: =SUMIF(Variables!$B$4:$B$15,Formato!D21,Variables!$C$4:$C$15) -> 1.53 | F21: 703 | G21: Costa | H21: 2011 | I21: =(C21-E21)*((Factores!$D$5*Factores!$L$4)+Factores!$N$4*Factores!$L$20+Factores!$P$4*Factores!$L$21)*Factores!$J$4*F21*Variables!$C$18 -> 2984.8805 | K21: =Factores!$J$4*C21*F21*(Factores!$D$5*Factores!$L$4+Factores!$N$4*Factores!$L$20+Factores!$P$4*Factores!$L$21)*Variables!$C$18 -> 6515.9633 | L21: =Factores!$J$4*E21*F21*(Factores!$D$5*Factores!$L$4+Factores!$N$4*Factores!$L$20+Factores!$P$4*Factores!$L$21)*Variables!$C$18 -> 3531.0828 | M21: =K21-L21 -> 2984.8805 | N21: =I21-M21 -> 0
B22: Tres piedras | C22: 2.8233333 | D22: Inkawasi Tawa | E22: =SUMIF(Variables!$B$4:$B$15,Formato!D22,Variables!$C$4:$C$15) -> 1.53 | F22: 66643 | G22: Sierra | H22: 2011 | I22: =(C22-E22)*((Factores!$E$5*Factores!$L$4)+Factores!$N$4*Factores!$L$20+Factores!$P$4*Factores!$L$21)*Factores!$J$4*F22*Variables!$C$18 -> 220012.44 | K22: =Factores!$J$4*C22*F22*(Factores!$E$5*Factores!$L$4+Factores!$N$4*Factores!$L$20+Factores!$P$4*Factores!$L$21)*Variables!$C$18 -> 480284.88 | L22: =Factores!$J$4*E22*F22*(Factores!$E$5*Factores!$L$4+Factores!$N$4*Factores!$L$20+Factores!$P$4*Factores!$L$21)*Variables!$C$18 -> 260272.44 | M22: =K22-L22 -> 220012.44 | N22: =I22-M22 -> 0
B23: Tres piedras | C23: 2.8233333 | D23: Inkawasi Plancha | E23: =SUMIF(Variables!$B$4:$B$15,Formato!D23,Variables!$C$4:$C$15) -> 1.9 | F23: 2650 | G23: Costa | H23: 2011 | I23: =(C23-E23)*((Factores!$D$5*Factores!$L$4)+Factores!$N$4*Factores!$L$20+Factores!$P$4*Factores!$L$21)*Factores!$J$4*F23*Variables!$C$18 -> 8032.7737 | K23: =Factores!$J$4*C23*F23*(Factores!$D$5*Factores!$L$4+Factores!$N$4*Factores!$L$20+Factores!$P$4*Factores!$L$21)*Variables!$C$18 -> 24562.308 | L23: =Factores!$J$4*E23*F23*(Factores!$D$5*Factores!$L$4+Factores!$N$4*Factores!$L$20+Factores!$P$4*Factores!$L$21)*Variables!$C$18 -> 16529.534 | M23: =K23-L23 -> 8032.7737 | N23: =I23-M23 -> 0
B24: Tres piedras | C24: 2.8233333 | D24: Inkawasi UK | E24: =SUMIF(Variables!$B$4:$B$15,Formato!D24,Variables!$C$4:$C$15) -> 2 | F24: 2422 | G24: Costa | H24: 2011 | I24: =(C24-E24)*((Factores!$D$5*Factores!$L$4)+Factores!$N$4*Factores!$L$20+Factores!$P$4*Factores!$L$21)*Factores!$J$4*F24*Variables!$C$18 -> 6546.5273 | K24: =Factores!$J$4*C24*F24*(Factores!$D$5*Factores!$L$4+Factores!$N$4*Factores!$L$20+Factores!$P$4*Factores!$L$21)*Variables!$C$18 -> 22449.023 | L24: =Factores!$J$4*E24*F24*(Factores!$D$5*Factores!$L$4+Factores!$N$4*Factores!$L$20+Factores!$P$4*Factores!$L$21)*Variables!$C$18 -> 15902.495 | M24: =K24-L24 -> 6546.5273 | N24: =I24-M24 -> 0
B25: Tres piedras | C25: 2.8233333 | D25: Inkawasi UK | E25: =SUMIF(Variables!$B$4:$B$15,Formato!D25,Variables!$C$4:$C$15) -> 2 | F25: 449 | G25: Sierra | H25: 2011 | I25: =(C25-E25)*((Factores!$E$5*Factores!$L$4)+Factores!$N$4*Factores!$L$20+Factores!$P$4*Factores!$L$21)*Factores!$J$4*F25*Variables!$C$18 -> 943.63548 | K25: =Factores!$J$4*C25*F25*(Factores!$E$5*Factores!$L$4+Factores!$N$4*Factores!$L$20+Factores!$P$4*Factores!$L$21)*Variables!$C$18 -> 3235.8674 | L25: =Factores!$J$4*E25*F25*(Factores!$E$5*Factores!$L$4+Factores!$N$4*Factores!$L$20+Factores!$P$4*Factores!$L$21)*Variables!$C$18 -> 2292.2319 | M25: =K25-L25 -> 943.63548 | N25: =I25-M25 -> 0
B26: Tres piedras | C26: 2.8233333 | D26: Mejorada Selva | E26: =SUMIF(Variables!$B$4:$B$15,Formato!D26,Variables!$C$4:$C$15) -> 1.16 | F26: 7326 | G26: Selva | H26: 2011 | I26: =(C26-E26)*((Factores!$F$5*Factores!$L$4)+Factores!$N$4*Factores!$L$20+Factores!$P$4*Factores!$L$21)*Factores!$J$4*F26*Variables!$C$18 -> 22205.383 | K26: =Factores!$J$4*C26*F26*(Factores!$F$5*Factores!$L$4+Factores!$N$4*Factores!$L$20+Factores!$P$4*Factores!$L$21)*Variables!$C$18 -> 37691.301 | L26: =Factores!$J$4*E26*F26*(Factores!$F$5*Factores!$L$4+Factores!$N$4*Factores!$L$20+Factores!$P$4*Factores!$L$21)*Variables!$C$18 -> 15485.918 | M26: =K26-L26 -> 22205.383 | N26: =I26-M26 -> 0
B27: Total | I27: =SUM(I16:I26) -> 490537.87
B28: Tres piedras | C28: 2.8233333 | D28: Amaray | E28: =SUMIF(Variables!$B$4:$B$15,Formato!D28,Variables!$C$4:$C$15) -> 1.92 | F28: 6 | G28: Sierra | H28: 2012 | I28: =(C28-E28)*((Factores!$E$6*Factores!$L$4)+Factores!$N$4*Factores!$L$20+Factores!$P$4*Factores!$L$21)*Factores!$J$4*F28*Variables!$C$18 -> 13.835075 | K28: =Factores!$J$4*C28*F28*(Factores!$E$6*Factores!$L$4+Factores!$N$4*Factores!$L$20+Factores!$P$4*Factores!$L$21)*Variables!$C$18 -> 43.24099 | L28: =Factores!$J$4*E28*F28*(Factores!$E$6*Factores!$L$4+Factores!$N$4*Factores!$L$20+Factores!$P$4*Factores!$L$21)*Variables!$C$18 -> 29.405915 | M28: =K28-L28 -> 13.835075 | N28: =I28-M28 -> 0
B29: Tres piedras | C29: 2.8233333 | D29: Inkawasi 3 Hornillas | E29: =SUMIF(Variables!$B$4:$B$15,Formato!D29,Variables!$C$4:$C$15) -> 1.42 | F29: 44022 | G29: Sierra | H29: 2012 | I29: =(C29-E29)*((Factores!$E$6*Factores!$L$4)+Factores!$N$4*Factores!$L$20+Factores!$P$4*Factores!$L$21)*Factores!$J$4*F29*Variables!$C$18 -> 157693.15 | K29: =Factores!$J$4*C29*F29*(Factores!$E$6*Factores!$L$4+Factores!$N$4*Factores!$L$20+Factores!$P$4*Factores!$L$21)*Variables!$C$18 -> 317259.14 | L29: =Factores!$J$4*E29*F29*(Factores!$E$6*Factores!$L$4+Factores!$N$4*Factores!$L$20+Factores!$P$4*Factores!$L$21)*Variables!$C$18 -> 159565.99 | M29: =K29-L29 -> 157693.15 | N29: =I29-M29 -> 0
B30: Tres piedras | C30: 2.8233333 | D30: Inkawasi Pichqa | E30: =SUMIF(Variables!$B$4:$B$15,Formato!D30,Variables!$C$4:$C$15) -> 0.84 | F30: 719 | G30: Costa | H30: 2012 | I30: =(C30-E30)*((Factores!$D$6*Factores!$L$4)+Factores!$N$4*Factores!$L$20+Factores!$P$4*Factores!$L$21)*Factores!$J$4*F30*Variables!$C$18 -> 4776.1861 | K30: =Factores!$J$4*C30*F30*(Factores!$D$6*Factores!$L$4+Factores!$N$4*Factores!$L$20+Factores!$P$4*Factores!$L$21)*Variables!$C$18 -> 6799.0414 | L30: =Factores!$J$4*E30*F30*(Factores!$D$6*Factores!$L$4+Factores!$N$4*Factores!$L$20+Factores!$P$4*Factores!$L$21)*Variables!$C$18 -> 2022.8553 | M30: =K30-L30 -> 4776.1861 | N30: =I30-M30 -> 0
B31: Tres piedras | C31: 2.8233333 | D31: Inkawasi Pichqa | E31: =SUMIF(Variables!$B$4:$B$15,Formato!D31,Variables!$C$4:$C$15) -> 0.84 | F31: 4702 | G31: Sierra | H31: 2012 | I31: =(C31-E31)*((Factores!$E$6*Factores!$L$4)+Factores!$N$4*Factores!$L$20+Factores!$P$4*Factores!$L$21)*Factores!$J$4*F31*Variables!$C$18 -> 23804.582 | K31: =Factores!$J$4*C31*F31*(Factores!$E$6*Factores!$L$4+Factores!$N$4*Factores!$L$20+Factores!$P$4*Factores!$L$21)*Variables!$C$18 -> 33886.522 | L31: =Factores!$J$4*E31*F31*(Factores!$E$6*Factores!$L$4+Factores!$N$4*Factores!$L$20+Factores!$P$4*Factores!$L$21)*Variables!$C$18 -> 10081.941 | M31: =K31-L31 -> 23804.582 | N31: =I31-M31 -> 0
B32: Tres piedras | C32: 2.8233333 | D32: Inkawasi Pichqa | E32: =SUMIF(Variables!$B$4:$B$15,Formato!D32,Variables!$C$4:$C$15) -> 0.84 | F32: 8659 | G32: Selva | H32: 2012 | I32: =(C32-E32)*((Factores!$F$6*Factores!$L$4)+Factores!$N$4*Factores!$L$20+Factores!$P$4*Factores!$L$21)*Factores!$J$4*F32*Variables!$C$18 -> 31295.04 | K32: =Factores!$J$4*C32*F32*(Factores!$F$6*Factores!$L$4+Factores!$N$4*Factores!$L$20+Factores!$P$4*Factores!$L$21)*Variables!$C$18 -> 44549.41 | L32: =Factores!$J$4*E32*F32*(Factores!$F$6*Factores!$L$4+Factores!$N$4*Factores!$L$20+Factores!$P$4*Factores!$L$21)*Variables!$C$18 -> 13254.37 | M32: =K32-L32 -> 31295.04 | N32: =I32-M32 -> 0
B33: Tres piedras | C33: 2.8233333 | D33: Inkawasi Sojta | E33: =SUMIF(Variables!$B$4:$B$15,Formato!D33,Variables!$C$4:$C$15) -> 1.8 | F33: 10845 | G33: Costa | H33: 2012 | I33: =(C33-E33)*((Factores!$D$6*Factores!$L$4)+Factores!$N$4*Factores!$L$20+Factores!$P$4*Factores!$L$21)*Factores!$J$4*F33*Variables!$C$18 -> 37170.921 | K33: =Factores!$J$4*C33*F33*(Factores!$D$6*Factores!$L$4+Factores!$N$4*Factores!$L$20+Factores!$P$4*Factores!$L$21)*Variables!$C$18 -> 102553 | L33: =Factores!$J$4*E33*F33*(Factores!$D$6*Factores!$L$4+Factores!$N$4*Factores!$L$20+Factores!$P$4*Factores!$L$21)*Variables!$C$18 -> 65382.076 | M33: =K33-L33 -> 37170.921 | N33: =I33-M33 -> 0
B34: Tres piedras | C34: 2.8233333 | D34: Inkawasi Sojta | E34: =SUMIF(Variables!$B$4:$B$15,Formato!D34,Variables!$C$4:$C$15) -> 1.8 | F34: 79 | G34: Sierra | H34: 2012 | I34: =(C34-E34)*((Factores!$E$6*Factores!$L$4)+Factores!$N$4*Factores!$L$20+Factores!$P$4*Factores!$L$21)*Factores!$J$4*F34*Variables!$C$18 -> 206.36043 | K34: =Factores!$J$4*C34*F34*(Factores!$E$6*Factores!$L$4+Factores!$N$4*Factores!$L$20+Factores!$P$4*Factores!$L$21)*Variables!$C$18 -> 569.3397 | L34: =Factores!$J$4*E34*F34*(Factores!$E$6*Factores!$L$4+Factores!$N$4*Factores!$L$20+Factores!$P$4*Factores!$L$21)*Variables!$C$18 -> 362.97926 | M34: =K34-L34 -> 206.36043 | N34: =I34-M34 -> 0
B35: Tres piedras | C35: 2.8233333 | D35: Inkawasi Tawa | E35: =SUMIF(Variables!$B$4:$B$15,Formato!D35,Variables!$C$4:$C$15) -> 1.53 | F35: 703 | G35: Costa | H35: 2012 | I35: =(C35-E35)*((Factores!$D$6*Factores!$L$4)+Factores!$N$4*Factores!$L$20+Factores!$P$4*Factores!$L$21)*Factores!$J$4*F35*Variables!$C$18 -> 3045.2464 | K35: =Factores!$J$4*C35*F35*(Factores!$D$6*Factores!$L$4+Factores!$N$4*Factores!$L$20+Factores!$P$4*Factores!$L$21)*Variables!$C$18 -> 6647.7415 | L35: =Factores!$J$4*E35*F35*(Factores!$D$6*Factores!$L$4+Factores!$N$4*Factores!$L$20+Factores!$P$4*Factores!$L$21)*Variables!$C$18 -> 3602.4951 | M35: =K35-L35 -> 3045.2464 | N35: =I35-M35 -> 0
B36: Tres piedras | C36: 2.8233333 | D36: Inkawasi Tawa | E36: =SUMIF(Variables!$B$4:$B$15,Formato!D36,Variables!$C$4:$C$15) -> 1.53 | F36: 66643 | G36: Sierra | H36: 2012 | I36: =(C36-E36)*((Factores!$E$6*Factores!$L$4)+Factores!$N$4*Factores!$L$20+Factores!$P$4*Factores!$L$21)*Factores!$J$4*F36*Variables!$C$18 -> 220012.44 | K36: =Factores!$J$4*C36*F36*(Factores!$E$6*Factores!$L$4+Factores!$N$4*Factores!$L$20+Factores!$P$4*Factores!$L$21)*Variables!$C$18 -> 480284.88 | L36: =Factores!$J$4*E36*F36*(Factores!$E$6*Factores!$L$4+Factores!$N$4*Factores!$L$20+Factores!$P$4*Factores!$L$21)*Variables!$C$18 -> 260272.44 | M36: =K36-L36 -> 220012.44 | N36: =I36-M36 -> 0
B37: Tres piedras | C37: 2.8233333 | D37: Inkawasi Plancha | E37: =SUMIF(Variables!$B$4:$B$15,Formato!D37,Variables!$C$4:$C$15) -> 1.9 | F37: 3379 | G37: Costa | H37: 2012 | I37: =(C37-E37)*((Factores!$D$6*Factores!$L$4)+Factores!$N$4*Factores!$L$20+Factores!$P$4*Factores!$L$21)*Factores!$J$4*F37*Variables!$C$18 -> 10449.689 | K37: =Factores!$J$4*C37*F37*(Factores!$D$6*Factores!$L$4+Factores!$N$4*Factores!$L$20+Factores!$P$4*Factores!$L$21)*Variables!$C$18 -> 31952.658 | L37: =Factores!$J$4*E37*F37*(Factores!$D$6*Factores!$L$4+Factores!$N$4*Factores!$L$20+Factores!$P$4*Factores!$L$21)*Variables!$C$18 -> 21502.969 | M37: =K37-L37 -> 10449.689 | N37: =I37-M37 -> 0
B38: Tres piedras | C38: 2.8233333 | D38: Inkawasi UK | E38: =SUMIF(Variables!$B$4:$B$15,Formato!D38,Variables!$C$4:$C$15) -> 2 | F38: 2422 | G38: Costa | H38: 2012 | I38: =(C38-E38)*((Factores!$D$6*Factores!$L$4)+Factores!$N$4*Factores!$L$20+Factores!$P$4*Factores!$L$21)*Factores!$J$4*F38*Variables!$C$18 -> 6678.9237 | K38: =Factores!$J$4*C38*F38*(Factores!$D$6*Factores!$L$4+Factores!$N$4*Factores!$L$20+Factores!$P$4*Factores!$L$21)*Variables!$C$18 -> 22903.03 | L38: =Factores!$J$4*E38*F38*(Factores!$D$6*Factores!$L$4+Factores!$N$4*Factores!$L$20+Factores!$P$4*Factores!$L$21)*Variables!$C$18 -> 16224.106 | M38: =K38-L38 -> 6678.9237 | N38: =I38-M38 -> 0
B39: Tres piedras | C39: 2.8233333 | D39: Inkawasi UK | E39: =SUMIF(Variables!$B$4:$B$15,Formato!D39,Variables!$C$4:$C$15) -> 2 | F39: 455 | G39: Sierra | H39: 2012 | I39: =(C39-E39)*((Factores!$E$6*Factores!$L$4)+Factores!$N$4*Factores!$L$20+Factores!$P$4*Factores!$L$21)*Factores!$J$4*F39*Variables!$C$18 -> 956.2453 | K39: =Factores!$J$4*C39*F39*(Factores!$E$6*Factores!$L$4+Factores!$N$4*Factores!$L$20+Factores!$P$4*Factores!$L$21)*Variables!$C$18 -> 3279.1084 | L39: =Factores!$J$4*E39*F39*(Factores!$E$6*Factores!$L$4+Factores!$N$4*Factores!$L$20+Factores!$P$4*Factores!$L$21)*Variables!$C$18 -> 2322.8631 | M39: =K39-L39 -> 956.2453 | N39: =I39-M39 -> 0
B40: Tres piedras | C40: 2.8233333 | D40: Mejorada Selva | E40: =SUMIF(Variables!$B$4:$B$15,Formato!D40,Variables!$C$4:$C$15) -> 1.16 | F40: 7326 | G40: Selva | H40: 2012 | I40: =(C40-E40)*((Factores!$F$6*Factores!$L$4)+Factores!$N$4*Factores!$L$20+Factores!$P$4*Factores!$L$21)*Factores!$J$4*F40*Variables!$C$18 -> 22205.383 | K40: =Factores!$J$4*C40*F40*(Factores!$F$6*Factores!$L$4+Factores!$N$4*Factores!$L$20+Factores!$P$4*Factores!$L$21)*Variables!$C$18 -> 37691.301 | L40: =Factores!$J$4*E40*F40*(Factores!$F$6*Factores!$L$4+Factores!$N$4*Factores!$L$20+Factores!$P$4*Factores!$L$21)*Variables!$C$18 -> 15485.918 | M40: =K40-L40 -> 22205.383 | N40: =I40-M40 -> 0
B41: Total | I41: =SUM(I28:I40) -> 518308
...

Sheet Variables
B2: Tipo | C2: Consumo (t leña/SA.año) | E2: Programa
B3: Tres piedras | C3: =[1]Consumos!$D$54 -> 2.8233333 | E3: NINA
B4: Inkawasi Tawa | C4: =[1]Consumos!$C$55 -> 1.53 | E4: Cocina Perú
B5: Inkawasi Pichqa | C5: =[1]Consumos!$C$58 -> 0.84 | E5: Mi Chacra emprendedora
B6: Inkawasi 3 Hornillas | C6: =[1]Consumos!$C$56 -> 1.42 | E6: HakuWiñay/Noa Jayatay
B7: Inkawasi Sojta | C7: 1.8 | E7: 50.000 Cocinas Mejoradas
B8: Inkawasi Plancha | C8: 1.9 | E8: Casita caliente
B9: Inkawasi UK | C9: 2 | E9: FISE
B10: Mejorada Selva | C10: =[1]Consumos!$C$59 -> 1.16 | E10: FAS
B11: Caralia | C11: =[1]Consumos!$C$55 -> 1.53 | E11: Otro
B12: Haku Wiñay (VA) | C12: =[1]Consumos!$C$57 -> 2.06
B13: Alto Andina | C13: 1.85
B14: Amaray | C14: 1.92
B15: Econofire | C15: 1.7
B18: Miembros familia | C18: 3.8

Sheet Factores
B2: Fracción de Biomasa no Renovable (fNRB) | I2: Combustible | J2: Poder calorífico | L2: Factor de emisión | T2: Industrias de la manufactura y construcción: 1A4b (Residencial)
B3: Año | C3: Conservador | D3: Costa | E3: Sierra | F3: Selva | G3: Fuente | J3: IPCC | K3: Unidad | L3: IPCC | M3: Unidad | N3: IPCC | O3: Unidad | P3: IPCC | Q3: Unidad | T3: Gas/contaminante | U3: CO (g/GJ) | V3: NOx (g/GJ) | W3: COVDM (g/GJ) | X3: SOX (g/GJ) | Y3: PM10 (g/GJ) | Z3: PM2.5 (g/GJ) | AA3: BC (g/GJ) | AB3: BC (%PM2.5) | AC3: EMEP/EEA air pollutant emission inventory guidebook 2016 1 - NFR 1.A.4.a.i, 1.A.4.b.i, 1.A.4.c.i, 1.A.5.a Small combustion
B4: 2010 | C4: 0.3 | D4: 0.4 | E4: 0.32 | F4: 0.28 | G4: Methodological tool: Calculation of the fraction of non-renewable biomass (Version 02.0) | I4: Biomasa (Madera) | J4: =15600/1000000 -> 0.0156 | K4: TJ/t | L4: =112000/1000 -> 112 | M4: tCO2/TJ | N4: =300/1000 -> 0.3 | O4: tCH4/TJ | P4: =4/1000 -> 0.004 | Q4: tN2O/TJ | T4: Biomass - Solid biomass | U4: 4000 | V4: 50 | W4: 600 | X4: 11 | Y4: 760 | Z4: 740 | AA4: =AB4/100*Z4 -> 74 | AB4: 10 | AC4: Table 3.6 Tier 1 emission factors for NFR source category 1.A.4.b, using biomass
B5: 2011 | C5: 0.3 | D5: 0.41 | E5: 0.3 | F5: 0.19 | G5: Methodological tool: Calculation of the fraction of non-renewable biomass (Version 02.0) | I5: GLP | J5: =0.0473*1000000/1000000 -> 0.0473 | K5: TJ/t | L5: =63100/1000 -> 63.1 | M5: tCO2/TJ | N5: =1/1000 -> 0.001 | O5: tCH4/TJ | P5: =0.1/1000 -> 0.0001 | Q5: tN2O/TJ | T5: Gas Licuado de Petróleo | U5: =U6 -> 26 | V5: =V6 -> 51 | W5: =W6 -> 1.9 | X5: =X6 -> 0.3 | Y5: =Y6 -> 1.2 | Z5: =Z6 -> 1.2 | AA5: =AA6 -> 0.0648 | AB5: =AB6 -> 5.4 | AC5: Table 3.4 Tier 1 emission factors for NFR source category 1.A.4.b, using gaseous fuels
B6: 2012 | C6: 0.3 | D6: 0.42 | E6: 0.3 | F6: 0.19 | G6: Methodological tool: Calculation of the fraction of non-renewable biomass (Version 02.0) | I6: Fuente: Directrices IPCC 2006 | T6: Gas natural - Gaseous fuels | U6: 26 | V6: 51 | W6: 1.9 | X6: 0.3 | Y6: 1.2 | Z6: 1.2 | AA6: =AB6/100*Z6 -> 0.0648 | AB6: 5.4 | AC6: Table 3.4 Tier 1 emission factors for NFR source category 1.A.4.b, using gaseous fuels
B7: 2013 | C7: 0.3 | D7: 0.42 | E7: 0.3 | F7: 0.19 | G7: Methodological tool: Calculation of the fraction of non-renewable biomass (Version 02.0) | T7: Diesel - Gas oil | U7: 57 | V7: 51 | W7: 0.69 | X7: 70 | Y7: 1.9 | Z7: 1.9 | AA7: =AB7/100*Z7 -> 0.1615 | AB7: 8.5 | AC7: Table 3.5 Tier 1 emission factors for NFR source category 1.A.4.b, using liquid fuels
B8: 2014 | C8: 0.3 | D8: 0.42 | E8: 0.3 | F8: 0.19 | G8: Methodological tool: Calculation of the fraction of non-renewable biomass (Version 02.0) | I8: Combustible | J8: Poder calorífico | T8: Carbón | U8: 4600 | V8: 110 | W8: 484 | X8: 900 | Y8: 404 | Z8: 398 | AA8: =AB8/100*Z8 -> 25.472 | AB8: 6.4 | AC8: Table 3.3 Tier 1 emission factors for NFR source category 1.A.4.b, using hard coal and brown coal
B9: 2015 | C9: 0.3 | D9: 0.42 | E9: 0.3 | F9: 0.19 | G9: Methodological tool: Calculation of the fraction of non-renewable biomass (Version 02.0) | J9: Estudio | K9: Unidad
B10: 2016 | C10: 0.3 | D10: 0.42 | E10: 0.3 | F10: 0.19 | G10: Methodological tool: Calculation of the fraction of non-renewable biomass (Version 02.0) | I10: Biomasa (Madera) | J10: ='[1]Energía y contenido de carbono'!$M$5/1000000000 -> 1.7412167e-05 | K10: TJ/kg | N10: =17275/1000000000 -> 1.7275e-05
B11: 2017 | C11: 0.3 | D11: 0.42 | E11: 0.3 | F11: 0.19 | G11: Methodological tool: Calculation of the fraction of non-renewable biomass (Version 02.0) | I11: Fuente: Directrices IPCC 2006 | N11: https://es.slideshare.net/slides_eoi/alfredo-lopez-mendiburu-acciona
B12: 2018 | C12: 0.3 | D12: 0.42 | E12: 0.3 | F12: 0.19 | G12: Methodological tool: Calculation of the fraction of non-renewable biomass (Version 02.0)
B13: 2019 | C13: 0.3 | D13: 0.42 | E13: 0.3 | F13: 0.19 | G13: Methodological tool: Calculation of the fraction of non-renewable biomass (Version 02.0) | I13: Ratio (tradicional/GLP)
B14: 2020 | C14: 0.3 | D14: 0.42 | E14: 0.3 | F14: 0.19 | G14: Methodological tool: Calculation of the fraction of non-renewable biomass (Version 02.0) | I14: ='[2]Calculos propios'!$T$6 -> 7.3806725 | J14: kg/kg
B15: 2021 | C15: 0.3 | D15: 0.42 | E15: 0.3 | F15: 0.19 | G15: Methodological tool: Calculation of the fraction of non-renewable biomass (Version 02.0) | I15: Fuente: Calculos propios
B16: 2022 | C16: 0.3 | D16: 0.42 | E16: 0.3 | F16: 0.19 | G16: Methodological tool: Calculation of the fraction of non-renewable biomass (Version 02.0)
B17: 2023 | C17: 0.3 | D17: 0.42 | E17: 0.3 | F17: 0.19 | G17: Methodological tool: Calculation of the fraction of non-renewable biomass (Version 02.0) | I17: Potencial de Calentamiento Global
B18: 2024 | C18: 0.3 | D18: 0.42 | E18: 0.3 | F18: 0.19 | G18: Methodological tool: Calculation of the fraction of non-renewable biomass (Version 02.0) | I18: GEI | J18: AR2 | K18: AR4 | L18: AR5
B19: 2025 | C19: 0.3 | D19: 0.42 | E19: 0.3 | F19: 0.19 | G19: Methodological tool: Calculation of the fraction of non-renewable biomass (Version 02.0) | I19: CO2 | J19: 1 | K19: 1 | L19: 1
B20: 2026 | C20: 0.3 | D20: 0.42 | E20: 0.3 | F20: 0.19 | G20: Methodological tool: Calculation of the fraction of non-renewable biomass (Version 02.0) | I20: CH4 | J20: 21 | K20: 25 | L20: 28
B21: 2027 | C21: 0.3 | D21: 0.42 | E21: 0.3 | F21: 0.19 | G21: Methodological tool: Calculation of the fraction of non-renewable biomass (Version 02.0) | I21: N2O | J21: 310 | K21: 298 | L21: 265
B22: 2028 | C22: 0.3 | D22: 0.42 | E22: 0.3 | F22: 0.19 | G22: Methodological tool: Calculation of the fraction of non-renewable biomass (Version 02.0) | I22: Fuente: Global Warming Potential Values - GHG Protocol
B23: 2029 | C23: 0.3 | D23: 0.42 | E23: 0.3 | F23: 0.19 | G23: Methodological tool: Calculation of the fraction of non-renewable biomass (Version 02.0) | I23: https://www.ghgprotocol.org/sites/default/files/ghgp/Global-Warming-Potential-Values%20%28Feb%2016%202016%29_1.pdf
B24: 2030 | C24: 0.3 | D24: 0.42 | E24: 0.3 | F24: 0.19 | G24: Methodological tool: Calculation of the fraction of non-renewable biomass (Version 02.0)
