Workbook
Name _ftn1: Proveedores!#REF!
Name _ftn2: Proveedores!#REF!
Name _ftnref1: Proveedores!#REF!
Name _ftnref2: Proveedores!#REF!
Name _Hlk511018708: Proveedores!$B$13

Sheet General
A2: 1.1 | B2: Etiquetado de Eficiencia Energética
B4: Esta medida de mitigación, propuesta por el Ministerio de Energía y Minas, propone que los equipos que requieran suministros energéticos incluyan en sus etiquetas, envases, empaques y publicidad, una etiqueta de eficiencia energética a través de la cual el consumidor pueda conocer el consumo de energía y la eficiencia energética del producto para la toma de decisión de consumo, reduciendo así las emisiones de GEI debido a la reducción del consumo de energía asociada a la mejora de eficiencia de los nuevos equipos a ser adquiridos por los consumidores. La medida se enmarca en el Reglamento Técnico sobre el etiquetado de eficiencia energética para equipos energéticos, aprobado mediante Decreto Supremo N°009-2017-EM.
B9: Medida | C9: Finalidad | D9: Indicadores | E9: Fuente (s)
B10: Etiquetado de Eficiencia Energética | C10: Dar cumplimiento al Reglamento Técnico sobre el etiquetado de eficiencia energética para equipos energéticos, aprobado mediante Decreto Supremo N°009-2017-EM. Puede incluir aparatos de refrigeración, calderas, motores eléctricos, lavadoras, secadoras, equipos de aire acondicionado y calentadores de agua. No incluye luminarias. Recomendacion: solo incluir campañas masivas, sello y linea de financiamiento (POR EJEMPLO COFIDE, FOFEE). | D10: Consumo eléctrico (según especificaciones de cada equipo) | E10: Estudios de mercado
B12: Metodología
B17: Dónde:
B18: ERy | C18: Reducción de emisiones en el año y (tCO2/año)
B19: ECBL,y | C19: Consumo de energía de la Línea Base en el año y (kWh/año)
B20: ECPJ,y | C20: Consumo de energía de las actividades de proyecto en el año y (kWh/año)
B21: TDy | C21: Promedio anual de pérdidas técnicas en la red
B22: 1/1000 | C22: Factor de conversión de kWh a MWh
B23: EFy | C23: Factor de emisión de la fuente de energía (tCO2/MWh)
B25: Priorizar equipos de mayor impacto
B28: Metodología (calentadores de agua u otros que consuman combustibles fósiles)
B30: ERy = [FCb,y ∙ NCVb,fuel ∙ (EFb,fuel,CO2 + EFb,fuel,CH4 ∙ PCGCH4 + EFb,fuel,N2O ∙ PCGN2O)] - [FCp,y ∙ NCVp,fuel ∙ (EFp,fuel,CO2 + EFp,fuel,CH4 ∙ PCGCH4 + EFp,fuel,N2O ∙ PCGN2O)]
B32: Donde:
B33: ERy | C33: Emisiones reducidas durante el año "y" en tCO2e
B34: FCb,y | C34: Cantidad de combustible consumido en la Línea de Base b durante un año "y"
B35: NCVb,fuel | C35: Valor Calorífico Neto del combustible
B36: EFb,fuel,CO2 | C36: Factor de emisión de CO2 del combustible de línea base
B37: EFb,fuel,CH4 | C37: Factor de emisión de CH4 del combustible de línea base
B38: EFb,fuel,N2O | C38: Factor de emisión de N2O del combustible de línea base
B39: FCp,y | C39: Cantidad de combustible consumido en proyecto durante un año "y" (t)
B40: NCVp,fuel | C40: Valor Calorífico Neto del combustible
B41: EFp,fuel,CO2 | C41: Factor de emisión de CO2 del combustible de proyecto
B42: EFp,fuel,CH4 | C42: Factor de emisión de CH4 del combustible de proyecto
B43: EFp,fuel,N2O | C43: Factor de emisión de N2O del combustible de proyecto
B44: PCGCH4 | C44: Potencial de Calentamiento Global del metano
B45: PCGN2O | C45: Potencial de Calentamiento Global del óxido nitroso

Sheet Proveedores
B2: 1.1. Medida de Etiquetado de Eficiencia energética
B4: PROVEEDORES | K4: INDICADORES
B5: Diseño detallado | D5: Programación Tentativa Sectorial | K5: Equipo | L5: Línea base | P5: Implementación
B6: 1. Encuestas | D6: 1. Fabricantes/importadores | L6: Tipo (si aplica) | M6: Etiqueta | N6: Potencia (W) | O6: Funcionamiento (horas.año) | P6: Tipo (si aplica) | Q6: Etiqueta | R6: Potencia (W) | S6: Funcionamiento (horas.año)
B7: 2. Estudio de mercado | D7: 2. Consumidores | K7: Refrigeradora
B8: 3. Aduanas-SUNAT | D8: 3. Aduanas SUNAT | K8: Lavadora
B9: Camara de Comercio de Lima | K9: Secadora
B10: Sello | K10: Calentador de agua
B11: Linea de financiamiento | K11: Aire acondicionado
K12: Motor eléctrico
B13: Etapa | C13: Información | D13: Fuente | E13: Responsable | F13: Frecuencia | G13: ¿Requiere acuerdo? | K13: Caldera
B14: Etiquetado de Eficiencia Energética
B15: M | C15: Efecto del etiquetado de eficiencia energética en la reducción del consumo | D15: Encuesta | E15: DGEE / INEI deben diseñar y realizar las encuestas | F15: Bienal | G15: Si, entre DGEE e INEI para las encuestas
B16: R | C16: Efecto del etiquetado de eficiencia energética en la reducción del consumo | D16: Resultados de las encuestas. INEI / DGEE | E16: DGEE debe vaciar la información en la herramienta de medición | F16: Bienal | G16: No
B17: V | C17: Reportes generados por DGEE, resultados de encuestas, procedimientos de medición, otra información de soporte | D17: DGEE | E17: Auditor externo | F17: Cada 3 años o según lo demanden algunas autoridades o donantes | G17: No

Sheet Formato
B1: Esta medida deberá ser llenada unicamente por el especialista encargado, se llenará a través de distintos estudios de mercado
B3: Refrigeradoras | D3: BaU | E3: Mitigación
B4: Capacidad (L) | C4: Categoría | D4: Etiqueta | E4: Etiqueta | F4: Cantidad | G4: Año | H4: Mes de adquisición | I4: Meses contables | J4: Fecha del registro | K4: Responsable del registro | L4: Institución | M4: Medio de verificación | N4: Emisiones de GEI reducidas (tCO2e)
B5: Capacidad de la refrigeradora en litros | C5: Según el Reglamento Técnico de EEE | D5: A, B, C, etc. | E5: A+++, B, C, etc. | F5: Número de unidades de este tipo, clase y descripción. | G5: Año al que corresponde el registro. | H5: Mes en el que se compraron las refrigeradoras | I5: Meses del año en los que se contabilizará la energía ahorrada | J5: DD/MM/AAAA en que se efectúa el registro en este formulario. | K5: Nombre del responsable del registro en este formulario. | L5: Nombre de institución que envío información | M5: Documento que avala los datos utilizados | N5: Emisiones que se evitaron
B6: 120 | C6: Categoría 1 | D6: D | E6: A | F6: 25000 | G6: 2010 | H6: Marzo | I6: =12-3 -> 9 | J6: 43889 | K6: Winer Zevallos | L6: DGEE | M6: Estudio de mercado | N6: =(Variables!G15-Variables!G12)/(1-Factores!$C$4)*1/1000*Factores!$Q$4*F6*I6/12 -> 1992.8422
B7: 120 | C7: Categoría 1 | D7: F | E7: A | F7: 25000 | G7: 2010 | H7: Setiembre | I7: =12-9 -> 3 | J7: 43889 | K7: Winer Zevallos | L7: DGEE | M7: Estudio de mercado | N7: =(Variables!G17-Variables!G12)/(1-Factores!$C$4)*1/1000*Factores!$Q$4*F7*I7/12 -> 1153.7507
B8: 225 | C8: Categoría 1 | D8: E | E8: A | F8: 25000 | G8: 2011 | H8: Febrero | I8: =12-2 -> 10 | J8: 43889 | K8: Winer Zevallos | L8: DGEE | M8: Estudio de mercado | N8: =(Variables!G23-Variables!G19)/(1-Factores!$C$5)*1/1000*Factores!$Q$5*F8*I8/12 -> 3349.1361
B9: 375 | C9: Categoría 1 | D9: C | E9: A | F9: 25000 | G9: 2011 | H9: Julio | I9: =12-7 -> 5 | J9: 43889 | K9: Winer Zevallos | L9: DGEE | M9: Estudio de mercado | N9: =(Variables!G28-Variables!G26)/(1-Factores!$C$5)*1/1000*Factores!$Q$5*F9*I9/12 -> 912.98067
B10: 480 | C10: Categoría 1 | D10: D | E10: A | F10: 25000 | G10: 2012 | H10: Enero | I10: =12-1 -> 11 | J10: 43889 | K10: Winer Zevallos | L10: DGEE | M10: Estudio de mercado | N10: =(Variables!G36-Variables!G33)/(1-Factores!$C$6)*1/1000*Factores!$Q$6*F10*I10/12 -> 3493.9464
B11: 225 | C11: Categoría 4 | D11: D | E11: A | F11: 25000 | G11: 2013 | H11: Julio | I11: =12-7 -> 5 | J11: 43889 | K11: Winer Zevallos | L11: DGEE | M11: Estudio de mercado | N11: =(Variables!Y22-Variables!Y19)/(1-Factores!$C$7)*1/1000*Factores!$Q$7*F11*I11/12 -> 1963.789
B14: Congeladoras | D14: BaU | E14: Mitigación
B15: Capacidad (L) | C15: Categoría | D15: Etiqueta | E15: Etiqueta | F15: Cantidad | G15: Año | H15: Mes de adquisición | I15: Meses contables | J15: Fecha del registro | K15: Responsable del registro | L15: Institución | M15: Medio de verificación | N15: Emisiones de GEI reducidas (tCO2e)
B16: Capacidad de la refrigeradora en litros | C16: Según el Reglamento Técnico de EEE | D16: A, B, C, etc. | E16: A+++, B, C, etc. | F16: Número de unidades de este tipo, clase y descripción. | G16: Año al que corresponde el registro. | H16: Mes en el que se compraron las congeladoras | I16: Meses del año en los que se contabilizará la energía ahorrada | J16: DD/MM/AAAA en que se efectúa el registro en este formulario. | K16: Nombre del responsable del registro en este formulario. | L16: Nombre de institución que envío información | M16: Documento que avala los datos utilizados | N16: Emisiones que se evitaron
B17: 700 + L | C17: Categoría 8 | D17: E | E17: A | F17: 26914 | G17: 2018 | H17: Abril | I17: =12-4 -> 8 | J17: 43524 | K17: Juan Perez | L17: CCL | M17: Carta xyz | N17: =(Variables!G78-Variables!G74)/(1-Factores!C12)*1/1000*Factores!Q12*F17*I17/12 -> 9406.8999
B19: 375 | C19: Categoría 8 | D19: E | E19: A | F19: 10000 | G19: 2015 | H19: Febrero | I19: 10 | J19: 43978 | N19: =(Variables!G64-Variables!G60)/(1-Factores!C9)*1/1000*Factores!Q9*F19*I19/12 -> 3823.4026
B20: 375 | C20: Categoría 9 | D20: D | E20: A | F20: 10000 | G20: 2015 | H20: Junio | I20: 6 | J20: 43978 | N20: =(Variables!K63-Variables!K60)/(1-Factores!C9)*1/1000*Factores!Q9*F20*I20/12 -> 1415.0165
B21: 375 | C21: Categoría 10 | D21: D | E21: A | F21: 10000 | G21: 2015 | H21: Mayo | I21: 7 | J21: 43978 | N21: =(Variables!P63-Variables!P60)/(1-Factores!C9)*1/1000*Factores!Q9*F21*I21/12 -> 1650.8526
B22: 575 | C22: Categoría 8 | D22: E | E22: A | F22: 10000 | G22: 2016 | H22: Marzo | I22: 9 | J22: 43978 | N22: =(Variables!G71-Variables!G67)/(1-Factores!C10)*1/1000*Factores!Q10*F22*I22/12 -> 3007.9993
B23: 375 | C23: Categoría 9 | D23: E | E23: A | F23: 10000 | G23: 2016 | H23: Junio | I23: 6 | J23: 43978 | N23: =(Variables!K64-Variables!K60)/(1-Factores!C10)*1/1000*Factores!Q10*F23*I23/12 -> 1200.0859
B24: 375 | C24: Categoría 10 | D24: C | E24: A | F24: 10000 | G24: 2016 | H24: Junio | I24: 6 | J24: 43978 | N24: =(Variables!P62-Variables!P60)/(1-Factores!C10)*1/1000*Factores!Q10*F24*I24/12 -> 604.62343
B25: 575 | C25: Categoría 8 | D25: D | E25: A | F25: 20000 | G25: 2017 | H25: Abril | I25: 8 | J25: 43978
B26: 575 | C26: Categoría 9 | D26: F | E26: A | F26: 20000 | G26: 2017 | H26: Marzo | I26: 9 | J26: 43978
B28: Calentadores de agua (eléctricos acumulación) | C28: BaU | E28: Mitigación
B29: Capacidad (L) | C29: Etiqueta | D29: Energético | E29: Etiqueta | F29: Energético | G29: Cantidad | H29: Año | I29: Mes de adquisición | J29: Meses contables | K29: Fecha del registro | L29: Responsable del registro | M29: Institución | N29: Medio de verificación | O29: Emisiones de GEI reducidas (tCO2e)
B30: Capacidad del calentador | C30: A, B, C, etc. | D30: Energía que hace funcionar al calentador | E30: A+++, B, C, etc. | F30: Energía que hace funcionar al calentador | G30: Número de unidades de este tipo, clase y descripción. | H30: Año al que corresponde el registro. | I30: Mes en el que se compraron los calentadores | J30: Meses del año en los que se contabilizará la energía ahorrada | K30: DD/MM/AAAA en que se efectúa el registro en este formulario. | L30: Nombre del responsable del registro en este formulario. | M30: Nombre de institución que envío información | N30: Documento que avala los datos utilizados | O30: Emisiones que se evitaron
B31: 50 | C31: E | D31: Electricidad | E31: A | F31: Electricidad | G31: 7000 | H31: 2014 | I31: Junio | J31: =12-6 -> 6 | K31: 43978 | L31: Juan Perez | M31: CCL | N31: Carta xyz | O31: =(Variables!F98-Variables!F94)/(1-Factores!$C$8)*1/1000*Factores!$Q$8*G31*J31/12 -> 604.86734
B32: 150 | C32: D | D32: Electricidad | E32: A | F32: Electricidad | G32: 2000 | H32: 2014 | I32: Mayo | J32: =12-5 -> 7 | K32: 43978 | L32: Juan Perez | M32: CCL | N32: Carta xyz | O32: =(Variables!F104-Variables!F101)/(1-Factores!$C$8)*1/1000*Factores!$Q$8*G32*J32/12 -> 847.15314
B33: 15 | C33: E | D33: Electricidad | E33: B | F33: Electricidad | G33: 45000 | H33: 2015 | I33: Abril | J33: 8 | K33: 43978 | L33: Juan Perez | M33: CCL | N33: Carta xyz | O33: =(Variables!F91-Variables!F88)/(1-Factores!$C$9)*1/1000*Factores!$Q$9*G33*J33/12 -> 932.10943
B34: 50 | C34: D | D34: Electricidad | E34: B | F34: Electricidad | G34: 4000 | H34: 2015 | I34: Febrero | J34: 10 | K34: 43978 | L34: Juan Perez | M34: CCL | N34: Carta xyz | O34: =(Variables!F97-Variables!F95)/(1-Factores!$C$9)*1/1000*Factores!$Q$9*G34*J34/12 -> 305.27043
B35: 50 | C35: E | D35: Electricidad | E35: A | F35: Electricidad | G35: 7000 | H35: 2016 | I35: Junio | J35: 6 | K35: 43978 | L35: Juan Perez | M35: CCL | N35: Carta xyz | O35: =(Variables!F98-Variables!F94)/(1-Factores!$C$10)*1/1000*Factores!$Q$10*G35*J35/12 -> 396.40506
B36: 150 | C36: D | D36: Electricidad | E36: A | F36: Electricidad | G36: 2000 | H36: 2016 | I36: Mayo | J36: 7 | K36: 43978 | L36: Juan Perez | M36: CCL | N36: Carta xyz | O36: =(Variables!F104-Variables!F101)/(1-Factores!$C$10)*1/1000*Factores!$Q$10*G36*J36/12 -> 555.18916
B39: Calentadores de agua (eléctricos instantaneo)
B40: BaU | D40: Mitigación
B41: Etiqueta | C41: Energético | D41: Etiqueta | E41: Energético | F41: Cantidad | G41: Año | H41: Mes de adquisición | I41: Meses contables | J41: Fecha del registro | K41: Responsable del registro | L41: Institución | M41: Medio de verificación | N41: Emisiones de GEI reducidas (tCO2e)
B42: A, B, C, etc. | C42: Energía que hace funcionar al calentador | D42: A+++, B, C, etc. | E42: Energía que hace funcionar al calentador | F42: Número de unidades de este tipo, clase y descripción. | G42: Año al que corresponde el registro. | H42: Mes en el que se compraron los calentadores | I42: Meses del año en los que se contabilizará la energía ahorrada | J42: DD/MM/AAAA en que se efectúa el registro en este formulario. | K42: Nombre del responsable del registro en este formulario. | L42: Nombre de institución que envío información | M42: Documento que avala los datos utilizados | N42: Emisiones que se evitaron
B43: C | C43: Electricidad | D43: A | E43: Electricidad | F43: 6170 | G43: 2013 | H43: Noviembre | I43: =12-11 -> 1 | J43: 43524 | K43: Juan Perez | L43: CCL | M43: Carta xyz | N43: =(Variables!J89-Variables!J87)/(1-Factores!$C$7)*1/1000*Factores!$Q$7*F43 -> 863.04812
B44: F | C44: Electricidad | D44: B
B45: G | C45: Electricidad | D45: B
B46: D | C46: Electricidad | D46: A
B53: Calentadores de agua (gas acumulación) | C53: BaU | E53: Mitigación
...

Sheet Variables
E1: 9 | F1: 10 | G1: 11 | H1: 15 | I1: 18 | J1: 20 | K1: 23 | L1: 25 | M1: 36 | N1: 40 | O1: 60 | P1: 80 | Q1: 100 | R1: 150 | S1: 200
D2: Lámparas
D3: Tipo | E3: Potencia (W) | P3: Sector | Q3: Uso diario (h) | R3: Uso anual (h)
D4: Incandescente | E4: 15 | F4: 25 | G4: 40 | H4: 60 | I4: 100 | J4: 150 | K4: 200 | P4: Residencial | Q4: 3.5 | R4: =Q4*365 -> 1277.5
D5: Fluorescente líneal | E5: 10 | F5: 18 | G5: 36 | H5: 60 | I5: 80 | J5: 100 | P5: Público | Q5: 8 | R5: =12*22*Q5 -> 2112
D6: Ahorrador (LFC) | E6: 9 | F6: 11 | G6: 15 | H6: 20 | I6: 23 | J6: 30 | P6: Comercial | Q6: 8 | R6: =12*22*Q6 -> 2112
D7: LED | E7: 3 | F7: 4 | G7: 6 | H7: 9 | I7: 11 | J7: 16 | K7: 20 | L7: 25 | M7: 35 | N7: 60 | P7: Industrial | Q7: 8 | R7: =12*22*Q7 -> 2112
D8: Etiqueta | R8: =12*22*Q8 -> 0
D10: REFRIGERADORAS
B11: Categorías de Reglamento Técnico EEE | D11: Tipo | E11: Capacidad (L) | F11: Etiqueta | G11: Consumo (kWh/año) | J11: Tipo | K11: Capacidad (L) | L11: Etiqueta | M11: Consumo (kWh/año) | P11: Tipo | Q11: Capacidad (L) | R11: Etiqueta | S11: Consumo (kWh/año) | V11: Tipo | W11: Capacidad (L) | X11: Etiqueta | Y11: Consumo (kWh/año) | AB11: Tipo | AC11: Capacidad (L) | AD11: Etiqueta | AE11: Consumo (kWh/año) | AH11: Tipo | AI11: Capacidad (L) | AJ11: Etiqueta | AK11: Consumo (kWh/año) | AN11: Tipo | AO11: Capacidad (L) | AP11: Etiqueta | AQ11: Consumo (kWh/año)
B12: Categoría 1 | D12: Categoría 1 | E12: 120 | F12: A | G12: =[1]Resumen!$D$4 -> 184.39432 | J12: Categoría 2 | K12: 120 | L12: A | M12: =[1]Resumen!$D$8 -> 176.64381 | P12: Categoría 3 | Q12: 120 | R12: A | S12: =[1]Resumen!$D$12 -> 189.9304 | V12: Categoría 4 | W12: 120 | X12: A | Y12: =[1]Resumen!$D$16 -> 227.27162 | AB12: Categoría 5 | AC12: 120 | AD12: A | AE12: =[1]Resumen!$D$20 -> 241.3708 | AH12: Categoría 6 | AI12: 120 | AJ12: A | AK12: =[1]Resumen!$D$24 -> 352.91907 | AN12: Categoría 7 | AO12: 120 | AP12: A | AQ12: =[1]Resumen!$D$28 -> 286.4576
B13: Categoría 2 | D13: Categoría 1 | E13: =+E12 -> 120 | F13: B | G13: =[1]Resumen!$E$4 -> 217.92056 | H13: =G13/G12-1 -> 0.18181818 | J13: Categoría 2 | K13: =+K12 -> 120 | L13: B | M13: =[1]Resumen!$E$8 -> 208.76086 | N13: =M13/M12-1 -> 0.18181818 | P13: Categoría 3 | Q13: =+Q12 -> 120 | R13: B | S13: =[1]Resumen!$E$12 -> 224.4632 | T13: =S13/S12-1 -> 0.18181818 | V13: Categoría 4 | W13: =+W12 -> 120 | X13: B | Y13: =[1]Resumen!$E$16 -> 268.59373 | Z13: =Y13/Y12-1 -> 0.18181818 | AB13: Categoría 5 | AC13: =+AC12 -> 120 | AD13: B | AE13: =[1]Resumen!$E$20 -> 285.2564 | AF13: =AE13/AE12-1 -> 0.18181818 | AH13: Categoría 6 | AI13: =+AI12 -> 120 | AJ13: B | AK13: =[1]Resumen!$E$24 -> 417.08618 | AL13: =AK13/AK12-1 -> 0.18181818 | AN13: Categoría 7 | AO13: =+AO12 -> 120 | AP13: B | AQ13: =[1]Resumen!$E$28 -> 338.5408 | AR13: =AQ13/AQ12-1 -> 0.18181818
B14: Categoría 3 | D14: Categoría 1 | E14: =+E13 -> 120 | F14: C | G14: =[1]Resumen!$F$4 -> 284.97304 | H14: =G14/G13-1 -> 0.30769231 | J14: Categoría 2 | K14: =+K13 -> 120 | L14: C | M14: =[1]Resumen!$F$8 -> 272.99498 | N14: =M14/M13-1 -> 0.30769231 | P14: Categoría 3 | Q14: =+Q13 -> 120 | R14: C | S14: =[1]Resumen!$F$12 -> 293.5288 | T14: =S14/S13-1 -> 0.30769231 | V14: Categoría 4 | W14: =+W13 -> 120 | X14: C | Y14: =[1]Resumen!$F$16 -> 351.23795 | Z14: =Y14/Y13-1 -> 0.30769231 | AB14: Categoría 5 | AC14: =+AC13 -> 120 | AD14: C | AE14: =[1]Resumen!$F$20 -> 373.0276 | AF14: =AE14/AE13-1 -> 0.30769231 | AH14: Categoría 6 | AI14: =+AI13 -> 120 | AJ14: C | AK14: =[1]Resumen!$F$24 -> 545.42038 | AL14: =AK14/AK13-1 -> 0.30769231 | AN14: Categoría 7 | AO14: =+AO13 -> 120 | AP14: C | AQ14: =[1]Resumen!$F$28 -> 442.7072 | AR14: =AQ14/AQ13-1 -> 0.30769231
B15: Categoría 4 | D15: Categoría 1 | E15: =+E14 -> 120 | F15: D | G15: =[1]Resumen!$G$4 -> 343.64396 | H15: =G15/G14-1 -> 0.20588235 | J15: Categoría 2 | K15: =+K14 -> 120 | L15: D | M15: =[1]Resumen!$G$8 -> 329.19982 | N15: =M15/M14-1 -> 0.20588235 | P15: Categoría 3 | Q15: =+Q14 -> 120 | R15: D | S15: =[1]Resumen!$G$12 -> 353.9612 | T15: =S15/S14-1 -> 0.20588235 | V15: Categoría 4 | W15: =+W14 -> 120 | X15: D | Y15: =[1]Resumen!$G$16 -> 423.55165 | Z15: =Y15/Y14-1 -> 0.20588235 | AB15: Categoría 5 | AC15: =+AC14 -> 120 | AD15: D | AE15: =[1]Resumen!$G$20 -> 449.8274 | AF15: =AE15/AE14-1 -> 0.20588235 | AH15: Categoría 6 | AI15: =+AI14 -> 120 | AJ15: D | AK15: =[1]Resumen!$G$24 -> 657.71282 | AL15: =AK15/AK14-1 -> 0.20588235 | AN15: Categoría 7 | AO15: =+AO14 -> 120 | AP15: D | AQ15: =[1]Resumen!$G$28 -> 533.8528 | AR15: =AQ15/AQ14-1 -> 0.20588235
B16: Categoría 5 | D16: Categoría 1 | E16: =+E15 -> 120 | F16: E | G16: =[1]Resumen!$H$4 -> 393.93332 | H16: =G16/G15-1 -> 0.14634146 | J16: Categoría 2 | K16: =+K15 -> 120 | L16: E | M16: =[1]Resumen!$H$8 -> 377.37541 | N16: =M16/M15-1 -> 0.14634146 | P16: Categoría 3 | Q16: =+Q15 -> 120 | R16: E | S16: =[1]Resumen!$H$12 -> 405.7604 | T16: =S16/S15-1 -> 0.14634146 | V16: Categoría 4 | W16: =+W15 -> 120 | X16: E | Y16: =[1]Resumen!$H$16 -> 485.53482 | Z16: =Y16/Y15-1 -> 0.14634146 | AB16: Categoría 5 | AC16: =+AC15 -> 120 | AD16: E | AE16: =[1]Resumen!$H$20 -> 515.6558 | AF16: =AE16/AE15-1 -> 0.14634146 | AH16: Categoría 6 | AI16: =+AI15 -> 120 | AJ16: E | AK16: =[1]Resumen!$H$24 -> 753.96347 | AL16: =AK16/AK15-1 -> 0.14634146 | AN16: Categoría 7 | AO16: =+AO15 -> 120 | AP16: E | AQ16: =[1]Resumen!$H$28 -> 611.9776 | AR16: =AQ16/AQ15-1 -> 0.14634146
B17: Categoría 6 | D17: Categoría 1 | E17: =+E16 -> 120 | F17: F | G17: =[1]Resumen!$I$4 -> 460.9858 | H17: =G17/G16-1 -> 0.17021277 | J17: Categoría 2 | K17: =+K16 -> 120 | L17: F | M17: =[1]Resumen!$I$8 -> 441.60952 | N17: =M17/M16-1 -> 0.17021277 | P17: Categoría 3 | Q17: =+Q16 -> 120 | R17: F | S17: =[1]Resumen!$I$12 -> 474.826 | T17: =S17/S16-1 -> 0.17021277 | V17: Categoría 4 | W17: =+W16 -> 120 | X17: F | Y17: =[1]Resumen!$I$16 -> 568.17904 | Z17: =Y17/Y16-1 -> 0.17021277 | AB17: Categoría 5 | AC17: =+AC16 -> 120 | AD17: F | AE17: =[1]Resumen!$I$20 -> 603.427 | AF17: =AE17/AE16-1 -> 0.17021277 | AH17: Categoría 6 | AI17: =+AI16 -> 120 | AJ17: F | AK17: =[1]Resumen!$I$24 -> 882.29768 | AL17: =AK17/AK16-1 -> 0.17021277 | AN17: Categoría 7 | AO17: =+AO16 -> 120 | AP17: F | AQ17: =[1]Resumen!$I$28 -> 716.144 | AR17: =AQ17/AQ16-1 -> 0.17021277
B18: Categoría 7 | D18: Categoría 1 | E18: =+E17 -> 120 | F18: G | G18: =[1]Resumen!$J$4 -> 502.8936 | H18: =G18/G17-1 -> 0.090909091 | J18: Categoría 2 | K18: =+K17 -> 120 | L18: G | M18: =[1]Resumen!$J$8 -> 481.75584 | N18: =M18/M17-1 -> 0.090909091 | P18: Categoría 3 | Q18: =+Q17 -> 120 | R18: G | S18: =[1]Resumen!$J$12 -> 517.992 | T18: =S18/S17-1 -> 0.090909091 | V18: Categoría 4 | W18: =+W17 -> 120 | X18: G | Y18: =[1]Resumen!$J$16 -> 619.83168 | Z18: =Y18/Y17-1 -> 0.090909091 | AB18: Categoría 5 | AC18: =+AC17 -> 120 | AD18: G | AE18: =[1]Resumen!$J$20 -> 658.284 | AF18: =AE18/AE17-1 -> 0.090909091 | AH18: Categoría 6 | AI18: =+AI17 -> 120 | AJ18: G | AK18: =[1]Resumen!$J$24 -> 962.50656 | AL18: =AK18/AK17-1 -> 0.090909091 | AN18: Categoría 7 | AO18: =+AO17 -> 120 | AP18: G | AQ18: =[1]Resumen!$J$28 -> 781.248 | AR18: =AQ18/AQ17-1 -> 0.090909091
D19: Categoría 1 | E19: 225 | F19: A | G19: =[1]Resumen!$D$5 -> 203.7706 | J19: Categoría 2 | K19: 225 | L19: A | M19: =[1]Resumen!$D$9 -> 189.23839 | P19: Categoría 3 | Q19: 225 | R19: A | S19: =[1]Resumen!$D$13 -> 214.15075 | V19: Categoría 4 | W19: 225 | X19: A | Y19: =[1]Resumen!$D$17 -> 310.15303 | AB19: Categoría 5 | AC19: 225 | AD19: A | AE19: =[1]Resumen!$D$21 -> 310.6015 | AH19: Categoría 6 | AI19: 225 | AJ19: A | AK19: =[1]Resumen!$D$25 -> 491.84201 | AN19: Categoría 7 | AO19: 225 | AP19: A | AQ19: =[1]Resumen!$D$29 -> 367.22675
B20: Capacidad | D20: Categoría 1 | E20: 225 | F20: B | G20: =[1]Resumen!$E$5 -> 240.8198 | H20: =G20/G19-1 -> 0.18181818 | J20: Categoría 2 | K20: 225 | L20: B | M20: =[1]Resumen!$E$9 -> 223.64537 | N20: =M20/M19-1 -> 0.18181818 | P20: Categoría 3 | Q20: 225 | R20: B | S20: =[1]Resumen!$E$13 -> 253.08725 | T20: =S20/S19-1 -> 0.18181818 | V20: Categoría 4 | W20: 225 | X20: B | Y20: =[1]Resumen!$E$17 -> 366.54449 | Z20: =Y20/Y19-1 -> 0.18181818 | AB20: Categoría 5 | AC20: 225 | AD20: B | AE20: =[1]Resumen!$E$21 -> 367.0745 | AF20: =AE20/AE19-1 -> 0.18181818 | AH20: Categoría 6 | AI20: 225 | AJ20: B | AK20: =[1]Resumen!$E$25 -> 581.26783 | AL20: =AK20/AK19-1 -> 0.18181818 | AN20: Categoría 7 | AO20: 225 | AP20: B | AQ20: =[1]Resumen!$E$29 -> 433.99525 | AR20: =AQ20/AQ19-1 -> 0.18181818
B21: 120 | D21: Categoría 1 | E21: 225 | F21: C | G21: =[1]Resumen!$F$5 -> 314.9182 | H21: =G21/G20-1 -> 0.30769231 | J21: Categoría 2 | K21: 225 | L21: C | M21: =[1]Resumen!$F$9 -> 292.45933 | N21: =M21/M20-1 -> 0.30769231 | P21: Categoría 3 | Q21: 225 | R21: C | S21: =[1]Resumen!$F$13 -> 330.96025 | T21: =S21/S20-1 -> 0.30769231 | V21: Categoría 4 | W21: 225 | X21: C | Y21: =[1]Resumen!$F$17 -> 479.32741 | Z21: =Y21/Y20-1 -> 0.30769231 | AB21: Categoría 5 | AC21: 225 | AD21: C | AE21: =[1]Resumen!$F$21 -> 480.0205 | AF21: =AE21/AE20-1 -> 0.30769231 | AH21: Categoría 6 | AI21: 225 | AJ21: C | AK21: =[1]Resumen!$F$25 -> 760.11947 | AL21: =AK21/AK20-1 -> 0.30769231 | AN21: Categoría 7 | AO21: 225 | AP21: C | AQ21: =[1]Resumen!$F$29 -> 567.53225 | AR21: =AQ21/AQ20-1 -> 0.30769231
B22: 225 | D22: Categoría 1 | E22: 225 | F22: D | G22: =[1]Resumen!$G$5 -> 379.7543 | H22: =G22/G21-1 -> 0.20588235 | J22: Categoría 2 | K22: 225 | L22: D | M22: =[1]Resumen!$G$9 -> 352.67154 | N22: =M22/M21-1 -> 0.20588235 | P22: Categoría 3 | Q22: 225 | R22: D | S22: =[1]Resumen!$G$13 -> 399.09912 | T22: =S22/S21-1 -> 0.20588235 | V22: Categoría 4 | W22: 225 | X22: D | Y22: =[1]Resumen!$G$17 -> 578.01247 | Z22: =Y22/Y21-1 -> 0.20588235 | AB22: Categoría 5 | AC22: 225 | AD22: D | AE22: =[1]Resumen!$G$21 -> 578.84825 | AF22: =AE22/AE21-1 -> 0.20588235 | AH22: Categoría 6 | AI22: 225 | AJ22: D | AK22: =[1]Resumen!$G$25 -> 916.61466 | AL22: =AK22/AK21-1 -> 0.20588235 | AN22: Categoría 7 | AO22: 225 | AP22: D | AQ22: =[1]Resumen!$G$29 -> 684.37712 | AR22: =AQ22/AQ21-1 -> 0.20588235
B23: 375 | D23: Categoría 1 | E23: 225 | F23: E | G23: =[1]Resumen!$H$5 -> 435.3281 | H23: =G23/G22-1 -> 0.14634146 | J23: Categoría 2 | K23: 225 | L23: E | M23: =[1]Resumen!$H$9 -> 404.28201 | N23: =M23/M22-1 -> 0.14634146 | P23: Categoría 3 | Q23: 225 | R23: E | S23: =[1]Resumen!$H$13 -> 457.50388 | T23: =S23/S22-1 -> 0.14634146 | V23: Categoría 4 | W23: 225 | X23: E | Y23: =[1]Resumen!$H$17 -> 662.59966 | Z23: =Y23/Y22-1 -> 0.14634146 | AB23: Categoría 5 | AC23: 225 | AD23: E | AE23: =[1]Resumen!$H$21 -> 663.55775 | AF23: =AE23/AE22-1 -> 0.14634146 | AH23: Categoría 6 | AI23: 225 | AJ23: E | AK23: =[1]Resumen!$H$25 -> 1050.7534 | AL23: =AK23/AK22-1 -> 0.14634146 | AN23: Categoría 7 | AO23: 225 | AP23: E | AQ23: =[1]Resumen!$H$29 -> 784.52987 | AR23: =AQ23/AQ22-1 -> 0.14634146
B24: 480 | D24: Categoría 1 | E24: 225 | F24: F | G24: =[1]Resumen!$I$5 -> 509.4265 | H24: =G24/G23-1 -> 0.17021277 | J24: Categoría 2 | K24: 225 | L24: F | M24: =[1]Resumen!$I$9 -> 473.09597 | N24: =M24/M23-1 -> 0.17021277 | P24: Categoría 3 | Q24: 225 | R24: F | S24: =[1]Resumen!$I$13 -> 535.37688 | T24: =S24/S23-1 -> 0.17021277 | V24: Categoría 4 | W24: 225 | X24: F | Y24: =[1]Resumen!$I$17 -> 775.38258 | Z24: =Y24/Y23-1 -> 0.17021277 | AB24: Categoría 5 | AC24: 225 | AD24: F | AE24: =[1]Resumen!$I$21 -> 776.50375 | AF24: =AE24/AE23-1 -> 0.17021277 | AH24: Categoría 6 | AI24: 225 | AJ24: F | AK24: =[1]Resumen!$I$25 -> 1229.605 | AL24: =AK24/AK23-1 -> 0.17021277 | AN24: Categoría 7 | AO24: 225 | AP24: F | AQ24: =[1]Resumen!$I$29 -> 918.06687 | AR24: =AQ24/AQ23-1 -> 0.17021277
D25: Categoría 1 | E25: 225 | F25: G | G25: =[1]Resumen!$J$5 -> 555.738 | H25: =G25/G24-1 -> 0.090909091 | J25: Categoría 2 | K25: 225 | L25: G | M25: =[1]Resumen!$J$9 -> 516.1047 | N25: =M25/M24-1 -> 0.090909091 | P25: Categoría 3 | Q25: 225 | R25: G | S25: =[1]Resumen!$J$13 -> 584.0475 | T25: =S25/S24-1 -> 0.090909091 | V25: Categoría 4 | W25: 225 | X25: G | Y25: =[1]Resumen!$J$17 -> 845.8719 | Z25: =Y25/Y24-1 -> 0.090909091 | AB25: Categoría 5 | AC25: 225 | AD25: G | AE25: =[1]Resumen!$J$21 -> 847.095 | AF25: =AE25/AE24-1 -> 0.090909091 | AH25: Categoría 6 | AI25: 225 | AJ25: G | AK25: =[1]Resumen!$J$25 -> 1341.3873 | AL25: =AK25/AK24-1 -> 0.090909091 | AN25: Categoría 7 | AO25: 225 | AP25: G | AQ25: =[1]Resumen!$J$29 -> 1001.5275 | AR25: =AQ25/AQ24-1 -> 0.090909091
D26: Categoría 1 | E26: 375 | F26: A | G26: =[1]Resumen!$D$6 -> 231.451 | J26: Categoría 2 | K26: 375 | L26: A | M26: =[1]Resumen!$D$10 -> 207.23065 | P26: Categoría 3 | Q26: 375 | R26: A | S26: =[1]Resumen!$D$14 -> 248.75125 | V26: Categoría 4 | W26: 375 | X26: A | Y26: =[1]Resumen!$D$18 -> 428.55505 | AB26: Categoría 5 | AC26: 375 | AD26: A | AE26: =[1]Resumen!$D$22 -> 409.5025 | AH26: Categoría 6 | AI26: 375 | AJ26: A | AK26: =[1]Resumen!$D$26 -> 690.30335 | AN26: Categoría 7 | AO26: 375 | AP26: A | AQ26: =[1]Resumen!$D$30 -> 482.61125
D27: Categoría 1 | E27: 375 | F27: B | G27: =[1]Resumen!$E$6 -> 273.533 | H27: =G27/G26-1 -> 0.18181818 | J27: Categoría 2 | K27: 375 | L27: B | M27: =[1]Resumen!$E$10 -> 244.90895 | N27: =M27/M26-1 -> 0.18181818 | P27: Categoría 3 | Q27: 375 | R27: B | S27: =[1]Resumen!$E$14 -> 293.97875 | T27: =S27/S26-1 -> 0.18181818 | V27: Categoría 4 | W27: 375 | X27: B | Y27: =[1]Resumen!$E$18 -> 506.47415 | Z27: =Y27/Y26-1 -> 0.18181818 | AB27: Categoría 5 | AC27: 375 | AD27: B | AE27: =[1]Resumen!$E$22 -> 483.9575 | AF27: =AE27/AE26-1 -> 0.18181818 | AH27: Categoría 6 | AI27: 375 | AJ27: B | AK27: =[1]Resumen!$E$26 -> 815.81305 | AL27: =AK27/AK26-1 -> 0.18181818 | AN27: Categoría 7 | AO27: 375 | AP27: B | AQ27: =[1]Resumen!$E$30 -> 570.35875 | AR27: =AQ27/AQ26-1 -> 0.18181818
D28: Categoría 1 | E28: 375 | F28: C | G28: =[1]Resumen!$F$6 -> 357.697 | H28: =G28/G27-1 -> 0.30769231 | J28: Categoría 2 | K28: 375 | L28: C | M28: =[1]Resumen!$F$10 -> 320.26555 | N28: =M28/M27-1 -> 0.30769231 | P28: Categoría 3 | Q28: 375 | R28: C | S28: =[1]Resumen!$F$14 -> 384.43375 | T28: =S28/S27-1 -> 0.30769231 | V28: Categoría 4 | W28: 375 | X28: C | Y28: =[1]Resumen!$F$18 -> 662.31235 | Z28: =Y28/Y27-1 -> 0.30769231 | AB28: Categoría 5 | AC28: 375 | AD28: C | AE28: =[1]Resumen!$F$22 -> 632.8675 | AF28: =AE28/AE27-1 -> 0.30769231 | AH28: Categoría 6 | AI28: 375 | AJ28: C | AK28: =[1]Resumen!$F$26 -> 1066.8324 | AL28: =AK28/AK27-1 -> 0.30769231 | AN28: Categoría 7 | AO28: 375 | AP28: C | AQ28: =[1]Resumen!$F$30 -> 745.85375 | AR28: =AQ28/AQ27-1 -> 0.30769231
D29: Categoría 1 | E29: 375 | F29: D | G29: =[1]Resumen!$G$6 -> 431.3405 | H29: =G29/G28-1 -> 0.20588235 | J29: Categoría 2 | K29: 375 | L29: D | M29: =[1]Resumen!$G$10 -> 386.20258 | N29: =M29/M28-1 -> 0.20588235 | P29: Categoría 3 | Q29: 375 | R29: D | S29: =[1]Resumen!$G$14 -> 463.58188 | T29: =S29/S28-1 -> 0.20588235 | V29: Categoría 4 | W29: 375 | X29: D | Y29: =[1]Resumen!$G$18 -> 798.67078 | Z29: =Y29/Y28-1 -> 0.20588235 | AB29: Categoría 5 | AC29: 375 | AD29: D | AE29: =[1]Resumen!$G$22 -> 763.16375 | AF29: =AE29/AE28-1 -> 0.20588235 | AH29: Categoría 6 | AI29: 375 | AJ29: D | AK29: =[1]Resumen!$G$26 -> 1286.4744 | AL29: =AK29/AK28-1 -> 0.20588235 | AN29: Categoría 7 | AO29: 375 | AP29: D | AQ29: =[1]Resumen!$G$30 -> 899.41188 | AR29: =AQ29/AQ28-1 -> 0.20588235
D30: Categoría 1 | E30: 375 | F30: E | G30: =[1]Resumen!$H$6 -> 494.4635 | H30: =G30/G29-1 -> 0.14634146 | J30: Categoría 2 | K30: 375 | L30: E | M30: =[1]Resumen!$H$10 -> 442.72003 | N30: =M30/M29-1 -> 0.14634146 | P30: Categoría 3 | Q30: 375 | R30: E | S30: =[1]Resumen!$H$14 -> 531.42313 | T30: =S30/S29-1 -> 0.14634146 | V30: Categoría 4 | W30: 375 | X30: E | Y30: =[1]Resumen!$H$22 -> 874.84625 | Z30: =Y30/Y29-1 -> 0.095377817 | AB30: Categoría 5 | AC30: 375 | AD30: E | AE30: =[1]Resumen!$H$22 -> 874.84625 | AF30: =AE30/AE29-1 -> 0.14634146 | AH30: Categoría 6 | AI30: 375 | AJ30: E | AK30: =[1]Resumen!$H$26 -> 1474.739 | AL30: =AK30/AK29-1 -> 0.14634146 | AN30: Categoría 7 | AO30: 375 | AP30: E | AQ30: =[1]Resumen!$H$30 -> 1031.0331 | AR30: =AQ30/AQ29-1 -> 0.14634146
D31: Categoría 1 | E31: 375 | F31: F | G31: =[1]Resumen!$I$6 -> 578.6275 | H31: =G31/G30-1 -> 0.17021277 | J31: Categoría 2 | K31: 375 | L31: F | M31: =[1]Resumen!$I$10 -> 518.07663 | N31: =M31/M30-1 -> 0.17021277 | P31: Categoría 3 | Q31: 375 | R31: F | S31: =[1]Resumen!$I$14 -> 621.87812 | T31: =S31/S30-1 -> 0.17021277 | V31: Categoría 4 | W31: 375 | X31: F | Y31: =[1]Resumen!$I$22 -> 1023.7563 | Z31: =Y31/Y30-1 -> 0.17021277 | AB31: Categoría 5 | AC31: 375 | AD31: F | AE31: =[1]Resumen!$I$22 -> 1023.7563 | AF31: =AE31/AE30-1 -> 0.17021277 | AH31: Categoría 6 | AI31: 375 | AJ31: F | AK31: =[1]Resumen!$I$26 -> 1725.7584 | AL31: =AK31/AK30-1 -> 0.17021277 | AN31: Categoría 7 | AO31: 375 | AP31: F | AQ31: =[1]Resumen!$I$30 -> 1206.5281 | AR31: =AQ31/AQ30-1 -> 0.17021277
D32: Categoría 1 | E32: 375 | F32: G | G32: =[1]Resumen!$J$6 -> 631.23 | H32: =G32/G31-1 -> 0.090909091 | J32: Categoría 2 | K32: 375 | L32: G | M32: =[1]Resumen!$J$10 -> 565.1745 | N32: =M32/M31-1 -> 0.090909091 | P32: Categoría 3 | Q32: 375 | R32: G | S32: =[1]Resumen!$J$14 -> 678.4125 | T32: =S32/S31-1 -> 0.090909091 | V32: Categoría 4 | W32: 375 | X32: G | Y32: =[1]Resumen!$J$22 -> 1116.825 | Z32: =Y32/Y31-1 -> 0.090909091 | AB32: Categoría 5 | AC32: 375 | AD32: G | AE32: =[1]Resumen!$J$22 -> 1116.825 | AF32: =AE32/AE31-1 -> 0.090909091 | AH32: Categoría 6 | AI32: 375 | AJ32: G | AK32: =[1]Resumen!$J$26 -> 1882.6455 | AL32: =AK32/AK31-1 -> 0.090909091 | AN32: Categoría 7 | AO32: 375 | AP32: G | AQ32: =[1]Resumen!$J$30 -> 1316.2125 | AR32: =AQ32/AQ31-1 -> 0.090909091
D33: Categoría 1 | E33: 480 | F33: A | G33: =[1]Resumen!$D$7 -> 250.82728 | J33: Categoría 2 | K33: 480 | L33: A | M33: =[1]Resumen!$D$11 -> 219.82523 | P33: Categoría 3 | Q33: 480 | R33: A | S33: =[1]Resumen!$D$15 -> 272.9716 | V33: Categoría 4 | W33: 480 | X33: A | Y33: =[1]Resumen!$D$19 -> 511.43646 | AB33: Categoría 5 | AC33: 480 | AD33: A | AE33: =[1]Resumen!$D$23 -> 478.7332 | AH33: Categoría 6 | AI33: 480 | AJ33: A | AK33: =[1]Resumen!$D$27 -> 829.22629 | AN33: Categoría 7 | AO33: 480 | AP33: A | AQ33: =[1]Resumen!$D$31 -> 563.3804
D34: Categoría 1 | E34: 480 | F34: B | G34: =[1]Resumen!$E$7 -> 296.43224 | H34: =G34/G33-1 -> 0.18181818 | J34: Categoría 2 | K34: 480 | L34: B | M34: =[1]Resumen!$E$11 -> 259.79346 | N34: =M34/M33-1 -> 0.18181818 | P34: Categoría 3 | Q34: 480 | R34: B | S34: =[1]Resumen!$E$15 -> 322.6028 | T34: =S34/S33-1 -> 0.18181818 | V34: Categoría 4 | W34: 480 | X34: B | Y34: =[1]Resumen!$E$19 -> 604.42491 | Z34: =Y34/Y33-1 -> 0.18181818 | AB34: Categoría 5 | AC34: 480 | AD34: B | AE34: =[1]Resumen!$E$23 -> 565.7756 | AF34: =AE34/AE33-1 -> 0.18181818 | AH34: Categoría 6 | AI34: 480 | AJ34: B | AK34: =[1]Resumen!$E$27 -> 979.9947 | AL34: =AK34/AK33-1 -> 0.18181818 | AN34: Categoría 7 | AO34: 480 | AP34: B | AQ34: =[1]Resumen!$E$31 -> 665.8132 | AR34: =AQ34/AQ33-1 -> 0.18181818
D35: Categoría 1 | E35: 480 | F35: C | G35: =[1]Resumen!$F$7 -> 387.64216 | H35: =G35/G34-1 -> 0.30769231 | J35: Categoría 2 | K35: 480 | L35: C | M35: =[1]Resumen!$F$11 -> 339.7299 | N35: =M35/M34-1 -> 0.30769231 | P35: Categoría 3 | Q35: 480 | R35: C | S35: =[1]Resumen!$F$15 -> 421.8652 | T35: =S35/S34-1 -> 0.30769231 | V35: Categoría 4 | W35: 480 | X35: C | Y35: =[1]Resumen!$F$19 -> 790.40181 | Z35: =Y35/Y34-1 -> 0.30769231 | AB35: Categoría 5 | AC35: 480 | AD35: C | AE35: =[1]Resumen!$F$23 -> 739.8604 | AF35: =AE35/AE34-1 -> 0.30769231 | AH35: Categoría 6 | AI35: 480 | AJ35: C | AK35: =[1]Resumen!$F$27 -> 1281.5315 | AL35: =AK35/AK34-1 -> 0.30769231 | AN35: Categoría 7 | AO35: 480 | AP35: C | AQ35: =[1]Resumen!$F$31 -> 870.6788 | AR35: =AQ35/AQ34-1 -> 0.30769231
D36: Categoría 1 | E36: 480 | F36: D | G36: =[1]Resumen!$G$7 -> 467.45084 | H36: =G36/G35-1 -> 0.20588235 | J36: Categoría 2 | K36: 480 | L36: D | M36: =[1]Resumen!$G$11 -> 409.6743 | N36: =M36/M35-1 -> 0.20588235 | P36: Categoría 3 | Q36: 480 | R36: D | S36: =[1]Resumen!$G$15 -> 508.7198 | T36: =S36/S35-1 -> 0.20588235 | V36: Categoría 4 | W36: 480 | X36: D | Y36: =[1]Resumen!$G$19 -> 953.13159 | Z36: =Y36/Y35-1 -> 0.20588235 | AB36: Categoría 5 | AC36: 480 | AD36: D | AE36: =[1]Resumen!$G$23 -> 892.1846 | AF36: =AE36/AE35-1 -> 0.20588235 | AH36: Categoría 6 | AI36: 480 | AJ36: D | AK36: =[1]Resumen!$G$27 -> 1545.3763 | AL36: =AK36/AK35-1 -> 0.20588235 | AN36: Categoría 7 | AO36: 480 | AP36: D | AQ36: =[1]Resumen!$G$31 -> 1049.9362 | AR36: =AQ36/AQ35-1 -> 0.20588235
D37: Categoría 1 | E37: 480 | F37: E | G37: =[1]Resumen!$H$7 -> 535.85828 | H37: =G37/G36-1 -> 0.14634146 | J37: Categoría 2 | K37: 480 | L37: E | M37: =[1]Resumen!$H$11 -> 469.62663 | N37: =M37/M36-1 -> 0.14634146 | P37: Categoría 3 | Q37: 480 | R37: E | S37: =[1]Resumen!$H$15 -> 583.1666 | T37: =S37/S36-1 -> 0.14634146 | V37: Categoría 4 | W37: 480 | X37: E | Y37: =[1]Resumen!$H$19 -> 1092.6143 | Z37: =Y37/Y36-1 -> 0.14634146 | AB37: Categoría 5 | AC37: 480 | AD37: E | AE37: =[1]Resumen!$H$23 -> 1022.7482 | AF37: =AE37/AE36-1 -> 0.14634146 | AH37: Categoría 6 | AI37: 480 | AJ37: E | AK37: =[1]Resumen!$H$27 -> 1771.5289 | AL37: =AK37/AK36-1 -> 0.14634146 | AN37: Categoría 7 | AO37: 480 | AP37: E | AQ37: =[1]Resumen!$H$31 -> 1203.5854 | AR37: =AQ37/AQ36-1 -> 0.14634146
D38: Categoría 1 | E38: 480 | F38: F | G38: =[1]Resumen!$I$7 -> 627.0682 | H38: =G38/G37-1 -> 0.17021277 | J38: Categoría 2 | K38: 480 | L38: F | M38: =[1]Resumen!$I$11 -> 549.56308 | N38: =M38/M37-1 -> 0.17021277 | P38: Categoría 3 | Q38: 480 | R38: F | S38: =[1]Resumen!$I$15 -> 682.429 | T38: =S38/S37-1 -> 0.17021277 | V38: Categoría 4 | W38: 480 | X38: F | Y38: =[1]Resumen!$I$19 -> 1278.5912 | Z38: =Y38/Y37-1 -> 0.17021277 | AB38: Categoría 5 | AC38: 480 | AD38: F | AE38: =[1]Resumen!$I$23 -> 1196.833 | AF38: =AE38/AE37-1 -> 0.17021277 | AH38: Categoría 6 | AI38: 480 | AJ38: F | AK38: =[1]Resumen!$I$27 -> 2073.0657 | AL38: =AK38/AK37-1 -> 0.17021277 | AN38: Categoría 7 | AO38: 480 | AP38: F | AQ38: =[1]Resumen!$I$31 -> 1408.451 | AR38: =AQ38/AQ37-1 -> 0.17021277
D39: Categoría 1 | E39: 480 | F39: G | G39: =[1]Resumen!$J$7 -> 684.0744 | H39: =G39/G38-1 -> 0.090909091 | J39: Categoría 2 | K39: 480 | L39: G | M39: =[1]Resumen!$J$11 -> 599.52336 | N39: =M39/M38-1 -> 0.090909091 | P39: Categoría 3 | Q39: 480 | R39: G | S39: =[1]Resumen!$J$15 -> 744.468 | T39: =S39/S38-1 -> 0.090909091 | V39: Categoría 4 | W39: 480 | X39: G | Y39: =[1]Resumen!$J$19 -> 1394.8267 | Z39: =Y39/Y38-1 -> 0.090909091 | AB39: Categoría 5 | AC39: 480 | AD39: G | AE39: =[1]Resumen!$J$23 -> 1305.636 | AF39: =AE39/AE38-1 -> 0.090909091 | AH39: Categoría 6 | AI39: 480 | AJ39: G | AK39: =[1]Resumen!$J$27 -> 2261.5262 | AL39: =AK39/AK38-1 -> 0.090909091 | AN39: Categoría 7 | AO39: 480 | AP39: G | AQ39: =[1]Resumen!$J$31 -> 1536.492 | AR39: =AQ39/AQ38-1 -> 0.090909091
D40: Categoría 1: Refrigerador con uno o más compartimientos de conservación de alimentos frescos. | J40: Categoría 2: Refrigerador - bodega, bodega y armarios para la conservación de vinos | P40: Categoría 3: Refrigerador - helador y refrigerador con un compartimento sin estrellas | V40: Categoría 4: Refrigerador con un compartimiento de una estrella | AB40: Categoría 5: Refrigerador con un compartimiento de dos estrellas | AH40: Categoría 6: Refrigerador con un compartimiento de tres estrellas | AN40: Categoría 7: Refrigerador congelador
D41: Fuente: Evaluación del Impacto del Reglamento Técnico sobre el Etiquetado de Eficiencia Energética para Equipos Energéticos (Entregable final) | J41: Fuente: Evaluación del Impacto del Reglamento Técnico sobre el Etiquetado de Eficiencia Energética para Equipos Energéticos (Entregable final) | P41: Fuente: Evaluación del Impacto del Reglamento Técnico sobre el Etiquetado de Eficiencia Energética para Equipos Energéticos (Entregable final) | V41: Fuente: Evaluación del Impacto del Reglamento Técnico sobre el Etiquetado de Eficiencia Energética para Equipos Energéticos (Entregable final) | AB41: Fuente: Evaluación del Impacto del Reglamento Técnico sobre el Etiquetado de Eficiencia Energética para Equipos Energéticos (Entregable final) | AH41: Fuente: Evaluación del Impacto del Reglamento Técnico sobre el Etiquetado de Eficiencia Energética para Equipos Energéticos (Entregable final) | AN41: Fuente: Evaluación del Impacto del Reglamento Técnico sobre el Etiquetado de Eficiencia Energética para Equipos Energéticos (Entregable final)
...

Sheet Factores
B2: Pérdidas por Transmisión y Distribución (TDy) | O2: Factor de emisión (EFy) de la fuente de energía (tCO2/MWh)
B3: Año | C3: TDy | D3: Fuente | O3: Año | P3: EFy (S/E) | Q3: EFy (mH) | R3: Fuente
B4: 2010 | C4: 0.104 | D4: http://www.minem.gob.pe/minem/archivos/Cap%C3%83%C2%ADtulo1_-%20Balance%20y%20Principales%20Indicadores%20El%C3%83%C2%A9ctricos%202010%20(2).pdf | O4: 2010 | Q4: =[4]Hoja1!$N$5 -> 0.598
B5: 2011 | C5: 0.108 | D5: http://www.minem.gob.pe/minem/archivos/Cap_1_%20%20Balance%20y%20Principales%20Indicadores%202011.pdf | O5: 2011 | Q5: =[4]Hoja1!$N$11 -> 0.61927
B6: 2012 | C6: 0.109 | D6: http://www.minem.gob.pe/minem/archivos/Capitulo%201%20%20Balance%20y%20Principales%20Indicadores%202012.pdf | O6: 2012 | Q6: =[4]Hoja1!$N$23 -> 0.6271
B7: 2013 | C7: 0.109 | D7: http://www.minem.gob.pe/minem/archivos/Capitulo%201%20%20Balance%20y%20Principales%20Indicadores%202013.pdf | O7: 2013 | Q7: =Q6 -> 0.6271
B8: 2014 | C8: =AVERAGE(C7,C9) -> 0.111 | D8: http://www.minem.gob.pe/minem/archivos/BALANCE%20E%20INDICADORES%202014.pdf | O8: 2014 | Q8: =Q7 -> 0.6271
B9: 2015 | C9: 0.113 | D9: http://www.minem.gob.pe/minem/archivos/Capitulo%201%20Indicadores%20FINAL.pdf | O9: 2015 | Q9: =Q8 -> 0.6271
B10: 2016 | C10: 0.109 | D10: http://www.minem.gob.pe/minem/archivos/Capitulo%201%20%20Balance%20e%20Indicadores%202016.pdf | O10: 2016 | P10: 0.4323 | Q10: 0.4119 | R10: Validation report for: “Emission factor calculation for the National Interconnected Electricity System of Peru (SEIN)”
B11: 2017 | C11: 0.108 | D11: http://www.minem.gob.pe/minem/archivos/Capitulo%201%20Balance%20e%20Indicadores%202017.pdf | O11: 2017 | P11: 0.4323 | Q11: 0.4119
B12: 2018 | C12: =C11 -> 0.108 | O12: 2018 | P12: 0.4323 | Q12: 0.4119
B13: 2019 | O13: 2019
B14: 2020 | O14: 2020
B15: 2021 | O15: 2021
B16: 2022 | O16: 2022
B17: 2023 | O17: 2023
B18: 2024 | O18: 2024
B19: 2025 | O19: 2025
B20: 2026 | O20: 2026
B21: 2027 | O21: 2027
B22: 2028 | O22: 2028
B23: 2029 | O23: 2029
B24: 2030 | O24: 2030
O25: Fuente: VALIDATION REPORT FOR “Emission factor calculation for the National Interconnected Electricity System of Peru (SEIN)”
B26: Valor calórico neto de combustibles | F26: Factores de emisión IPCC
B27: Combustible | C27: VCN | D27: Unidades | F27: Combustible | G27: kgCO2/TJ | H27: kgCH4/TJ | I27: kgN2O/TJ | J27: kgCO2e/TJ
B28: Gas Natural | C28: ='[5]Fact. con.'!E180 -> 3.6036968e-05 | D28: ='[5]Fact. con.'!F180 -> TJ/m3 | F28: Gas Natural | G28: ='[5]FE CE'!$F$39 -> 56126.263 | H28: ='[5]FE CE'!I24 -> 1 | I28: ='[5]FE CE'!L24 -> 0.1
B29: GLP | C29: ='[5]Fact. con.'!E179 -> 0.026392697 | D29: ='[5]Fact. con.'!F179 -> TJ/m3 | F29: GLP | G29: ='[5]FE CE'!F16 -> 63100 | H29: ='[5]FE CE'!I16 -> 1 | I29: ='[5]FE CE'!L16 -> 0.1
B30: Gas Natural | C30: =C28/('[5]Fact. con.'!$J$106*1000000) -> 4.5755735e-05 | D30: TJ/kg | F30: Fuente: Directrices IPCC 2006
B31: GLP | C31: =C29/('[5]Fact. con.'!$J$98*1000000) -> 4.730519e-05 | D31: TJ/kg | F31: Fuente (gas natural): Calculos propios
B32: Fuente: RAGEI 2016
B34: Potencial de Calentamiento Global
B35: GEI | C35: AR2 | D35: AR4 | E35: AR5
B36: CO2 | C36: 1 | D36: 1 | E36: 1
B37: CH4 | C37: 21 | D37: 25 | E37: 30
B38: N2O | C38: 310 | D38: 298 | E38: 265
B39: Fuente: Global Warming Potential Values - GHG Protocol
B40: https://www.ghgprotocol.org/sites/default/files/ghgp/Global-Warming-Potential-Values%20%28Feb%2016%202016%29_1.pdf
